Workbook

Sheet Notes
A1: =C4&" "&C3&" RIAPA CGE Model" -> 2019 Rwanda RIAPA CGE Model
A3: * | B3: Country | C3: Rwanda
A4: * | B4: Base year | C4: 2019
A5: * | B5: Units | C5: Billions of Rwandan Francs
A10: Activities (a) and commodities (c) | E10: Factors (f) | I10: Households (hhd) | M10: Other accounts
A11: cere | B11: Cereals | E11: lab-n | F11: Labor - uneducated | I11: f1 | J11: Rural farm - quintile 1 | M11: trc | N11: Transaction costs
A12: puls | B12: Pulses | E12: lab-p | F12: Labor - primary | I12: f2 | J12: Rural farm - quintile 2 | M12: ent | N12: Enterprises
A13: oils | B13: Oilseeds | E13: lab-s | F13: Labor - secondary | I13: f3 | J13: Rural farm - quintile 3 | M13: gov | N13: Government
A14: root | B14: Roots and Tubers | E14: lab-t | F14: Labor - tertiary | I14: f4 | J14: Rural farm - quintile 4 | M14: atax | N14: Taxes - activity
A15: vege | B15: Vegetables | E15: lnd | F15: Land - agricultural crops | I15: f5 | J15: Rural farm - quintile 5 | M15: dtax | N15: Taxes - direct
A16: frui | B16: Fruits | E16: cap-c | F16: Capital - crops | I16: n1 | J16: Rural nonfarm - quintile 1 | M16: etax | N16: Taxes - export
A17: becr | B17: Beverage crops | E17: cap-l | F17: Capital - livestock | I17: n2 | J17: Rural nonfarm - quintile 2 | M17: ftax | N17: Taxes - factor
A18: ocrp | B18: Other non-food crops | E18: cap-m | F18: Capital - mining | I18: n3 | J18: Rural nonfarm - quintile 3 | M18: mtax | N18: Taxes - import
A19: live | B19: Livestock | E19: cap-o | F19: Capital - other | I19: n4 | J19: Rural nonfarm - quintile 4 | M19: stax | N19: Taxes - sales
A20: milk | B20: Raw milk | I20: n5 | J20: Rural nonfarm - quintile 5 | M20: s-i | N20: Savings-investment
A21: fore | B21: Forestry | I21: u1 | J21: Urban - quintile 1 | M21: dstk | N21: Change in stocks
A22: fish | B22: Fishery | I22: u2 | J22: Urban - quintile 2 | M22: row | N22: Rest of world
A23: mine | B23: Mining - energy | I23: u3 | J23: Urban - quintile 3 | M23: total | N23: Total
A24: mino | B24: Mining - other | I24: u4 | J24: Urban - quintile 4
A25: gmll | B25: Grain milling | I25: u5 | J25: Urban - quintile 5
A26: foil | B26: Fats and oils
A27: fveg | B27: Fruit and vegetable processing
A28: meat | B28: Meat processing
A29: fsea | B29: Fish and seafood processing
A30: dair | B30: Dairy
A31: fobe | B31: Other food and beverages
A32: oapr | B32: Other processing of ag products
A33: text | B33: Textiles
A34: wood | B34: Wood products
A35: petr | B35: Petroleum products
A36: fert | B36: Fertilizers and herbicides
A37: chem | B37: Chemicals
... A56: osrv | B56: Other services

Sheet Index
A1: GAMS GDX Index
A2: Instruction | B2: Do not alter this sheet.
D7: rdim | E7: cdim
A8: par | B8: nsam | C8: sam!a7 | D8: 1 | E8: 1
D15: rdim | E15: cdim
A16: dset | B16: ac | C16: sets!a7 | D16: 1
A17: dset | B17: rg | C17: sets!b7 | D17: 1
A18: dset | B18: a | C18: sets!c7 | D18: 1
A19: dset | B19: arg | C19: sets!d7 | D19: 1
A20: dset | B20: c | C20: sets!e7 | D20: 1
A21: dset | B21: f | C21: sets!f7 | D21: 1
A22: dset | B22: flab | C22: sets!g7 | D22: 1
A23: dset | B23: flnd | C23: sets!h7 | D23: 1
A24: dset | B24: fliv | C24: sets!i7 | D24: 1
A25: dset | B25: fcap | C25: sets!j7 | D25: 1
A26: dset | B26: ins | C26: sets!k7 | D26: 1
A27: dset | B27: insd | C27: sets!l7 | D27: 1
... A33: dset | B33: ctm | C33: sets!r7 | D33: 1
A34: set | B34: mac | C34: sets!t7 | D34: 2 | F34: values=nodata
A35: set | B35: marg | C35: sets!w7 | D35: 3 | F35: values=nodata
A36: dset | B36: eagr | C36: sets!aa7 | D36: 1
A37: dset | B37: emin | C37: sets!ab7 | D37: 1
A38: dset | B38: eman | C38: sets!ac7 | D38: 1
A39: dset | B39: eutl | C39: sets!ad7 | D39: 1
A40: dset | B40: econ | C40: sets!ae7 | D40: 1
A41: dset | B41: etrd | C41: sets!af7 | D41: 1
A42: dset | B42: etrc | C42: sets!ag7 | D42: 1
A43: dset | B43: ehfs | C43: sets!ah7 | D43: 1
A44: dset | B44: efbs | C44: sets!ai7 | D44: 1
A45: dset | B45: eres | C45: sets!aj7 | D45: 1
A46: dset | B46: egsv | C46: sets!ak7 | D46: 1
A47: dset | B47: eosv | C47: sets!al7 | D47: 1
... A53: dset | B53: cer | C53: adjust!f7 | D53: 1
A54: par | B54: sam | C54: sam!a7 | D54: 1 | E54: 1
A55: par | B55: leselas1 | C55: LES!b131 | D55: 1 | E55: 1
A56: par | B56: leselas2 | C56: LES!s131 | D56: 1 | E56: 1
A57: par | B57: FRISCH | C57: LES!C206 | E57: 1
A58: par | B58: tradelas | C58: elasticities!a7 | D58: 1 | E58: 1
A59: par | B59: prodelastab | C59: elasticities!e7 | D59: 1 | E59: 1
A60: par | B60: proddata | C60: production!a7 | D60: 1 | E60: 2
...

Sheet Sets
A1: Set Definitions
A2: Instruction | B2: Do not alter this sheet, unless you are adding new regions.
A4: Global set | B4: Regions | C4: Activities | E4: Commodities | F4: Factors | K4: Institutions | P4: Transaction costs | T4: Mapping activities to commodities | W4: Mapping activities to regions | AA4: Sectoral groups for employment calculations
C5: All | F5: All | G5: Labor | H5: Land | I5: Livestock | J5: Capital | K5: All | L5: Domestic | M5: Non-government | N5: Enterprises | O5: Households | P5: Domestic | Q5: Export | R5: Import | T5: MAC | W5: MARG | AA5: Agriculture | AB5: Industry
A6: AC | B6: RG | C6: A | D6: ARG | E6: C | F6: F | G6: FLAB | H6: FLND | I6: FLIV | J6: FCAP | K6: INS | L6: INSD | M6: INSDNG | N6: EN | O6: H | P6: CTD | Q6: CTE | R6: CTM | T6: A | U6: C | W6: ARG | X6: A | Y6: RG | AA6: EAGR | AB6: EMIN | AC6: EMAN | AD6: EUTL | AE6: ECON | AF6: ETRD | AG6: ETRC | AH6: EHFS | AI6: EFBS | AJ6: ERES | AK6: EGSV | AL6: EOSV
A7: acere | B7: x | C7: acere | D7: acere | E7: ccere | F7: flab-n | G7: flab-n | H7: flnd | I7: fcap-l | J7: fcap-c | K7: ent | L7: ent | M7: ent | N7: ent | O7: hhd-f1 | P7: trd | Q7: tre | R7: trm | T7: =C7 -> acere | U7: =E7 -> ccere | W7: =D7 -> acere | X7: =C7 -> acere | Y7: x | AA7: =W7 -> acere | AB7: =W19 -> amine | AC7: =W21 -> agmll | AD7: aelec | AE7: acons | AF7: atrad | AG7: atran | AH7: ahotl | AI7: afsrv | AJ7: areal | AK7: apadm | AL7: aosrv
A8: apuls | C8: apuls | D8: apuls | E8: cpuls | F8: flab-p | G8: flab-p | J8: fcap-m | K8: hhd-f1 | L8: hhd-f1 | M8: hhd-f1 | O8: hhd-f2 | T8: =C8 -> apuls | U8: =E8 -> cpuls | W8: =D8 -> apuls | X8: =C8 -> apuls | Y8: x | AA8: =W8 -> apuls | AB8: =W20 -> amino | AC8: =W22 -> afoil | AD8: awatr | AG8: acomm | AH8: arest | AJ8: absrv | AK8: aeduc
A9: aoils | C9: aoils | D9: aoils | E9: coils | F9: flab-s | G9: flab-s | J9: fcap-o | K9: hhd-f2 | L9: hhd-f2 | M9: hhd-f2 | O9: hhd-f3 | T9: =C9 -> aoils | U9: =E9 -> coils | W9: =D9 -> aoils | X9: =C9 -> aoils | Y9: x | AA9: =W9 -> aoils | AC9: =W23 -> afveg | AK9: aheal
A10: aroot | C10: aroot | D10: aroot | E10: croot | F10: flab-t | G10: flab-t | K10: hhd-f3 | L10: hhd-f3 | M10: hhd-f3 | O10: hhd-f4 | T10: =C10 -> aroot | U10: =E10 -> croot | W10: =D10 -> aroot | X10: =C10 -> aroot | Y10: x | AA10: =W10 -> aroot | AC10: =W24 -> ameat
A11: avege | C11: avege | D11: avege | E11: cvege | F11: flnd | K11: hhd-f4 | L11: hhd-f4 | M11: hhd-f4 | O11: hhd-f5 | T11: =C11 -> avege | U11: =E11 -> cvege | W11: =D11 -> avege | X11: =C11 -> avege | Y11: x | AA11: =W11 -> avege | AC11: =W25 -> afsea
A12: afrui | C12: afrui | D12: afrui | E12: cfrui | F12: fcap-c | K12: hhd-f5 | L12: hhd-f5 | M12: hhd-f5 | O12: hhd-n1 | T12: =C12 -> afrui | U12: =E12 -> cfrui | W12: =D12 -> afrui | X12: =C12 -> afrui | Y12: x | AA12: =W12 -> afrui | AC12: =W26 -> adair
A13: abecr | C13: abecr | D13: abecr | E13: cbecr | F13: fcap-l | K13: hhd-n1 | L13: hhd-n1 | M13: hhd-n1 | O13: hhd-n2 | T13: abecr | U13: cbecr | W13: abecr | X13: abecr | Y13: x | AA13: abecr | AC13: =W27 -> afobe
A14: aocrp | C14: aocrp | D14: aocrp | E14: cocrp | F14: fcap-m | K14: hhd-n2 | L14: hhd-n2 | M14: hhd-n2 | O14: hhd-n3 | T14: =C14 -> aocrp | U14: =E14 -> cocrp | W14: =D14 -> aocrp | X14: =C14 -> aocrp | Y14: x | AA14: =W14 -> aocrp | AC14: =W28 -> aoapr
A15: alive | C15: alive | D15: alive | E15: clive | F15: fcap-o | K15: hhd-n3 | L15: hhd-n3 | M15: hhd-n3 | O15: hhd-n4 | T15: =C15 -> alive | U15: =E15 -> clive | W15: =D15 -> alive | X15: =C15 -> alive | Y15: x | AA15: =W15 -> alive | AC15: =W29 -> atext
A16: amilk | C16: amilk | D16: amilk | E16: cmilk | K16: hhd-n4 | L16: hhd-n4 | M16: hhd-n4 | O16: hhd-n5 | T16: =C16 -> amilk | U16: =E16 -> cmilk | W16: =D16 -> amilk | X16: =C16 -> amilk | Y16: x | AA16: =W16 -> amilk | AC16: =W30 -> awood
A17: afore | C17: afore | D17: afore | E17: cfore | K17: hhd-n5 | L17: hhd-n5 | M17: hhd-n5 | O17: hhd-u1 | T17: =C17 -> afore | U17: =E17 -> cfore | W17: =D17 -> afore | X17: =C17 -> afore | Y17: x | AA17: =W17 -> afore | AC17: =W31 -> apetr
A18: afish | C18: afish | D18: afish | E18: cfish | K18: hhd-u1 | L18: hhd-u1 | M18: hhd-u1 | O18: hhd-u2 | T18: =C18 -> afish | U18: =E18 -> cfish | W18: =D18 -> afish | X18: =C18 -> afish | Y18: x | AA18: =W18 -> afish | AC18: =W32 -> afert
A19: amine | C19: amine | D19: amine | E19: cmine | K19: hhd-u2 | L19: hhd-u2 | M19: hhd-u2 | O19: hhd-u3 | T19: =C19 -> amine | U19: =E19 -> cmine | W19: =D19 -> amine | X19: =C19 -> amine | Y19: x | AC19: =W33 -> achem
A20: amino | C20: amino | D20: amino | E20: cmino | K20: hhd-u3 | L20: hhd-u3 | M20: hhd-u3 | O20: hhd-u4 | T20: =C20 -> amino | U20: =E20 -> cmino | W20: =D20 -> amino | X20: =C20 -> amino | Y20: x | AC20: =W34 -> anmet
A21: agmll | C21: agmll | D21: agmll | E21: cgmll | K21: hhd-u4 | L21: hhd-u4 | M21: hhd-u4 | O21: hhd-u5 | T21: =C21 -> agmll | U21: =E21 -> cgmll | W21: =D21 -> agmll | X21: =C21 -> agmll | Y21: x | AC21: =W35 -> ametl
A22: afoil | C22: afoil | D22: afoil | E22: cfoil | K22: hhd-u5 | L22: hhd-u5 | M22: hhd-u5 | T22: =C22 -> afoil | U22: =E22 -> cfoil | W22: =D22 -> afoil | X22: =C22 -> afoil | Y22: x | AC22: =W36 -> amach
A23: afveg | C23: afveg | D23: afveg | E23: cfveg | K23: gov | L23: gov | T23: =C23 -> afveg | U23: =E23 -> cfveg | W23: =D23 -> afveg | X23: =C23 -> afveg | Y23: x | AC23: =W37 -> aoman
A24: ameat | C24: ameat | D24: ameat | E24: cmeat | K24: row | T24: =C24 -> ameat | U24: =E24 -> cmeat | W24: =D24 -> ameat | X24: =C24 -> ameat | Y24: x
A25: afsea | C25: afsea | D25: afsea | E25: cfsea | T25: =C25 -> afsea | U25: =E25 -> cfsea | W25: =D25 -> afsea | X25: =C25 -> afsea | Y25: x
A26: adair | C26: adair | D26: adair | E26: cdair | T26: =C26 -> adair | U26: =E26 -> cdair | W26: =D26 -> adair | X26: =C26 -> adair | Y26: x
A27: afobe | C27: afobe | D27: afobe | E27: cfobe | T27: =C27 -> afobe | U27: =E27 -> cfobe | W27: =D27 -> afobe | X27: =C27 -> afobe | Y27: x
A28: aoapr | C28: aoapr | D28: aoapr | E28: coapr | T28: =C28 -> aoapr | U28: =E28 -> coapr | W28: =D28 -> aoapr | X28: =C28 -> aoapr | Y28: x
A29: atext | C29: atext | D29: atext | E29: ctext | T29: =C29 -> atext | U29: =E29 -> ctext | W29: =D29 -> atext | X29: =C29 -> atext | Y29: x
A30: awood | C30: awood | D30: awood | E30: cwood | T30: =C30 -> awood | U30: =E30 -> cwood | W30: =D30 -> awood | X30: =C30 -> awood | Y30: x
A31: apetr | C31: apetr | D31: apetr | E31: cpetr | T31: =C31 -> apetr | U31: =E31 -> cpetr | W31: =D31 -> apetr | X31: =C31 -> apetr | Y31: x
A32: afert | C32: afert | D32: afert | E32: cfert | T32: =C32 -> afert | U32: =E32 -> cfert | W32: =D32 -> afert | X32: =C32 -> afert | Y32: x
A33: achem | C33: achem | D33: achem | E33: cchem | T33: =C33 -> achem | U33: =E33 -> cchem | W33: =D33 -> achem | X33: =C33 -> achem | Y33: x
A34: anmet | C34: anmet | D34: anmet | E34: cnmet | T34: =C34 -> anmet | U34: =E34 -> cnmet | W34: =D34 -> anmet | X34: =C34 -> anmet | Y34: x
A35: ametl | C35: ametl | D35: ametl | E35: cmetl | T35: =C35 -> ametl | U35: =E35 -> cmetl | W35: =D35 -> ametl | X35: =C35 -> ametl | Y35: x
A36: amach | C36: amach | D36: amach | E36: cmach | T36: =C36 -> amach | U36: =E36 -> cmach | W36: =D36 -> amach | X36: =C36 -> amach | Y36: x
... A52: aosrv | C52: aosrv | D52: aosrv | E52: cosrv | T52: =C52 -> aosrv | U52: =E52 -> cosrv | W52: =D52 -> aosrv | X52: =C52 -> aosrv | Y52: x
A53: ccere
A54: cpuls
A55: coils
A56: croot
...

Sheet Adjust
A1: Adjustments to SAM Trade Flows
A3: * | B3: * | C3: * | D3: * | E3: * | F3: *
A4: Remove small trade shares | C4: Re-exports | D4: Net out trade | F4: Perfect substitutes
A5: Exports | B5: Imports | D5: Exports | E5: Imports | F5: Exports
A6: REMEXP | B6: REMIMP | C6: REEXPORT | D6: NETEXPS | E6: NETIMPS | F6: CER | K6: VAshr | L6: PRDshr | M6: EMPshr | N6: EXPshr | O6: EXP-OUTshr | P6: IMPshr | Q6: IMP-DEMshr
B7: clive | D7: cfsrv | E7: cpuls | J7: ccere | K7: 1.7859389 | L7: 1.1397621 | M7: 3.4352083 | P7: 0.64118867 | Q7: 12.7526
B8: cmine | D8: cheal | E8: cvege | J8: cpuls | K8: 1.4410933 | L8: 0.90124884 | M8: 3.3298736 | N8: 1.85945 | O8: 32.301065
B9: cheal | D9: cosrv | E9: cfrui | J9: coils | K9: 0.57823985 | L9: 0.45952805 | M9: 1.2140011 | P9: 0.21887973 | Q9: 10.647417
B10: cosrv | J10: croot | K10: 6.0068381 | L10: 3.8276188 | M10: 11.883446
J11: cvege | K11: 0.98224881 | L11: 0.60294225 | M11: 2.1754799 | N11: 1.5644154 | O11: 32.113531
J12: cfrui | K12: 3.6539123 | L12: 2.2272571 | M12: 8.0290801 | N12: 2.4975494 | O12: 17.572612
J13: cbecr | K13: 1.599627 | L13: 1.4584081 | M13: 4.601759 | N13: 10.029369 | O13: 79.829316
J14: cocrp | K14: 0.069902725 | L14: 0.045074561 | M14: 0.15435798 | N14: 0.162142 | O14: 44.299758
J15: clive | K15: 1.7191152 | L15: 1.2291168 | M15: 3.3736601
J16: cmilk | K16: 1.0958969 | L16: 0.81059328 | M16: 1.6903128
J17: cfore | K17: 6.3964122 | L17: 4.1953 | M17: 22.436112
J18: cfish | K18: 0.39768199 | L18: 0.24726316 | M18: 1.561841
J19: cmine | K19: 0.048513412 | L19: 0.035239379 | M19: 0.0073630343
J20: cmino | K20: 1.5362705 | L20: 1.3206146 | M20: 1.1344224 | N20: 14.499061 | O20: 77.7582 | P20: 0.43852641 | Q20: 29.212594
J21: cgmll | K21: 0.54262426 | L21: 1.0316 | M21: 0.35258413 | P21: 0.69580552 | Q21: 13.920561
J22: cfoil | K22: 0.31590893 | L22: 0.39656911 | M22: 0.21954933 | P22: 1.1120045 | Q22: 40.879359
J23: cfveg | K23: 0.1392824 | L23: 0.25458225 | M23: 0.079739733 | P23: 0.08598798 | Q23: 7.4842282
J24: cmeat | K24: 0.25724115 | L24: 0.74586553 | M24: 0.14846489
J25: cfsea | K25: 0.0027541765 | L25: 0.0074333964 | M25: 0.0017476103 | P25: 0.47985947 | Q25: 94.008746
J26: cdair | K26: 0.19137364 | L26: 0.20478729 | M26: 0.12866561 | P26: 0.19111259 | Q26: 38.45558
J27: cfobe | K27: 3.5544526 | L27: 4.8755869 | M27: 1.1986042 | N27: 2.9745679 | O27: 8.8152801 | P27: 2.8519078 | Q27: 15.210634
J28: coapr | K28: 0.24268468 | L28: 0.26241306 | M28: 0.078950296 | P28: 0.10298444 | Q28: 8.2937748
J29: ctext | K29: 0.83019902 | L29: 1.0218093 | M29: 0.42845425 | P29: 4.1965053 | Q29: 51.859839
J30: cwood | K30: 0.39985639 | L30: 0.50896392 | M30: 0.15198191 | P30: 2.499274 | Q30: 54.266281
J31: cpetr | K31: 0.0069941474 | L31: 0.0048947301 | M31: 0.00041044037 | P31: 16.462606 | Q31: 99.871464
J32: cfert | P32: 3.151409 | Q32: 100
J33: cchem | K33: 0.65497188 | L33: 0.78113772 | M33: 0.045533145 | N33: 4.6202424 | O33: 64.276993 | P33: 9.9891939 | Q33: 89.505921
J34: cnmet | K34: 0.53529082 | L34: 0.69050836 | M34: 0.16142002 | N34: 2.5220564 | O34: 39.658391 | P34: 2.1742647 | Q34: 55.892731
J35: cmetl | K35: 0.15913926 | L35: 0.53093956 | M35: 0.065098562 | P35: 9.0039449 | Q35: 80.308813
J36: cmach | K36: 1.081371 | L36: 0.95111132 | M36: 0.47244052 | P36: 24.314897 | Q36: 86.19234
J37: coman | K37: 0.22979396 | L37: 0.22306967 | M37: 0.079111167 | P37: 0.74900002 | Q37: 44.130362
J38: celec | K38: 1.1948186 | L38: 1.5433985 | M38: 0.2451767
J39: cwatr | K39: 0.5099012 | L39: 0.530125 | M39: 0.11845646
J40: ccons | K40: 8.1952173 | L40: 13.043909 | M40: 6.1549163
J41: ctrad | K41: 9.8505778 | L41: 9.8618079 | M41: 10.60763
...

Sheet SAM
A1: Nexus Social Accounting Matrix
A2: Instruction | B2: Do not alter this sheet. This data is exported from x1aggregate.gms and x1aggregate.xlsx files, which aggregates the original SAM into the standard Nexus SAM structure.
B5: =B104/SUM(B100:B108) -> 0.47094117 | C5: =C104/SUM(C100:C108) -> 0.34589964 | D5: =D104/SUM(D100:D108) -> 0.44280743 | E5: =E104/SUM(E100:E108) -> 0.47171801 | F5: =F104/SUM(F100:F108) -> 0.39275717 | G5: =G104/SUM(G100:G108) -> 0.20980197 | H5: =H104/SUM(H100:H108) -> 0.34010801 | I5: =I104/SUM(I100:I108) -> 0.39526124 | J5: {=SUM(B104:I104/SUM(B100:I106))} -> 0.41063561
B7: acere | C7: apuls | D7: aoils | E7: aroot | F7: avege | G7: abecr | H7: aocrp | I7: afrui | J7: alive | K7: amilk | L7: afore | M7: afish | N7: amine | O7: amino | P7: ameat | Q7: afsea | R7: afveg | S7: afoil | T7: adair | U7: agmll | V7: afobe | W7: aoapr | X7: atext | Y7: awood | Z7: apetr | AA7: achem | AB7: anmet | AC7: ametl | AD7: amach | AE7: aoman | AF7: aelec | AG7: awatr | AH7: acons | AI7: atrad | AJ7: atran | AK7: ahotl | AL7: arest | AM7: acomm | AN7: afsrv | AO7: areal | AP7: absrv | AQ7: apadm | AR7: aeduc | AS7: aheal | AT7: aosrv | AU7: ccere | AV7: cpuls | AW7: coils | AX7: croot | AY7: cvege | AZ7: cbecr | BA7: cocrp | BB7: cfrui | BC7: clive | BD7: cmilk | BE7: cfore | BF7: cfish | BG7: cmine | BH7: cmino | BI7: cmeat | BJ7: cfsea | BK7: cfveg | BL7: cfoil | BM7: cdair | BN7: cgmll | BO7: cfobe | BP7: coapr | BQ7: ctext | BR7: cwood | BS7: cpetr | BT7: cfert | BU7: cchem | BV7: cnmet | BW7: cmetl | BX7: cmach | BY7: coman | BZ7: celec | CA7: cwatr | CB7: ccons | CC7: ctrad | CD7: ctran | CE7: chotl | CF7: crest | CG7: ccomm | CH7: cfsrv | CI7: creal | CJ7: cbsrv | CK7: cpadm | CL7: ceduc | CM7: cheal | CN7: cosrv | CO7: trc | CP7: flab-n | CQ7: flab-p | CR7: flab-s | CS7: flab-t | CT7: flnd | CU7: fcap-c | CV7: fcap-l | CW7: fcap-m | CX7: fcap-o | CY7: ent | CZ7: hhd-f1 | DA7: hhd-f2 | DB7: hhd-f3 | DC7: hhd-f4 | DD7: hhd-f5 | DE7: hhd-n1 | DF7: hhd-n2 | DG7: hhd-n3 | DH7: hhd-n4 | DI7: hhd-n5 | DJ7: hhd-u1 | DK7: hhd-u2 | DL7: hhd-u3 | DM7: hhd-u4 | DN7: hhd-u5 | DO7: gov | DP7: dtax | DQ7: mtax | DR7: stax | DS7: s-i | DT7: row | DU7: total
A8: acere | AU8: 145.09821 | CZ8: 1.7820724 | DA8: 3.1392521 | DB8: 3.4494678 | DC8: 4.2713719 | DD8: 1.8633422 | DE8: 0.29108973 | DF8: 0.72137474 | DG8: 0.60155906 | DH8: 0.7359538 | DI8: 0.41571703 | DJ8: 0.024624876 | DK8: 0.086573363 | DL8: 0.075457568 | DM8: 0.14457011 | DN8: 0.2121983 | DU8: 162.91284
A9: apuls | AV9: 99.520762 | CZ9: 2.4893385 | DA9: 4.2393935 | DB9: 5.6110611 | DC9: 7.0294043 | DD9: 3.928866 | DE9: 0.56070403 | DF9: 0.93306068 | DG9: 1.0558421 | DH9: 1.0823772 | DI9: 0.60731415 | DJ9: 0.071234165 | DK9: 0.13987332 | DL9: 0.24626211 | DM9: 0.40529715 | DN9: 0.89996177 | DU9: 128.82075
A10: aoils | AW10: 60.304902 | CZ10: 0.066754537 | DA10: 0.47476601 | DB10: 0.51146258 | DC10: 2.050175 | DD10: 1.2453566 | DE10: 0.11179547 | DF10: 0.19114966 | DH10: 0.34784657 | DI10: 0.03358021 | DM10: 0.020303787 | DN10: 0.32493121 | DU10: 65.683023
A11: aroot | AX11: 325.84099 | CZ11: 17.039033 | DA11: 33.437974 | DB11: 46.567662 | DC11: 54.837768 | DD11: 26.865786 | DE11: 3.798836 | DF11: 6.6830325 | DG11: 9.3374122 | DH11: 9.1941426 | DI11: 4.3758533 | DJ11: 0.37170609 | DK11: 1.4679745 | DL11: 1.6377807 | DM11: 2.0660144 | DN11: 3.5819084 | DU11: 547.10388
A12: avege | AY12: 78.999376 | CZ12: 0.98642824 | DA12: 1.129752 | DB12: 1.3454564 | DC12: 1.3456928 | DD12: 0.69813728 | DE12: 0.21015605 | DF12: 0.22810182 | DG12: 0.23602143 | DH12: 0.19301601 | DI12: 0.15412739 | DJ12: 0.068304876 | DK12: 0.086814327 | DL12: 0.11652082 | DM12: 0.13546358 | DN12: 0.24868201 | DU12: 86.182051
A13: abecr | AZ13: 207.09947 | CZ13: 0.020909498 | DA13: 0.14862248 | DB13: 0.160102 | DC13: 0.64028896 | DD13: 0.3893766 | DU13: 208.45877
A14: aocrp | BA14: 6.2139681 | CZ14: 0.0031915993 | DA14: 0.0075054861 | DB14: 6.7278264e-05 | DC14: 0.0322881 | DD14: 0.085926117 | DH14: 0.07796561 | DN14: 0.021857578 | DU14: 6.4427698
A15: afrui | BB15: 238.8893 | CZ15: 3.9033868 | DA15: 7.4907735 | DB15: 12.816528 | DC15: 21.126911 | DD15: 16.380037 | DE15: 0.57414547 | DF15: 1.97384 | DG15: 2.1171639 | DH15: 2.9894256 | DI15: 2.2074637 | DJ15: 0.095860698 | DK15: 0.33230953 | DL15: 1.1139412 | DM15: 1.4695902 | DN15: 4.8741653 | DU15: 318.35484
A16: alive | BC16: 159.5966 | CZ16: 0.46639921 | DA16: 0.95987788 | DB16: 1.5816904 | DC16: 2.6660497 | DD16: 4.3651155 | DE16: 0.090104946 | DF16: 0.1667572 | DG16: 0.26375588 | DH16: 0.55935128 | DI16: 0.69822616 | DJ16: 0.015205968 | DK16: 0.053003564 | DL16: 0.038825463 | DM16: 0.072125097 | DN16: 4.0917431 | DU16: 175.68484
A17: amilk | BD17: 82.94532 | CZ17: 0.29871704 | DA17: 1.8652035 | DB17: 3.4592336 | DC17: 9.0587726 | DD17: 10.36788 | DE17: 0.036381651 | DF17: 0.26036541 | DG17: 0.5942017 | DH17: 1.2106905 | DI17: 0.63797885 | DJ17: 0.015797378 | DK17: 0.1772489 | DL17: 0.32283471 | DM17: 0.92540094 | DN17: 3.6867976 | DU17: 115.86282
A18: afore | BE18: 69.964671 | CZ18: 79.115102 | DA18: 90.832292 | DB18: 98.451839 | DC18: 97.144046 | DD18: 52.975167 | DE18: 12.233701 | DF18: 14.676812 | DG18: 13.341029 | DH18: 14.344895 | DI18: 8.2614425 | DJ18: 5.7746827 | DK18: 7.9225168 | DL18: 11.369502 | DM18: 14.319446 | DN18: 8.9315511 | DU18: 599.6587
A19: afish | BF19: 33.642323 | CZ19: 0.11437143 | DA19: 0.28374004 | DB19: 0.47849884 | DC19: 0.32159525 | DD19: 0.43390641 | DE19: 0.0019076325 | DF19: 0.010221411 | DG19: 0.039596287 | DH19: 0.016605131 | DU19: 35.342765
A20: amine | BG20: 5.0369699 | DU20: 5.0369699
A21: amino | BH21: 188.76315 | DU21: 188.76315
A22: ameat | BI22: 106.61091 | DU22: 106.61091
A23: afsea | BJ23: 1.0624987 | DU23: 1.0624987
A24: afveg | BK24: 36.388926 | DU24: 36.388926
A25: afoil | BL25: 56.683936 | DU25: 56.683936
A26: adair | BM26: 9.5578741 | CZ26: 0.40362686 | DA26: 1.6233443 | DB26: 2.8280152 | DC26: 6.0225056 | DD26: 5.2531041 | DE26: 0.10996782 | DF26: 0.47454756 | DG26: 0.46336986 | DH26: 0.9219724 | DI26: 0.36630071 | DJ26: 0.068747358 | DL26: 0.32053678 | DM26: 0.48395548 | DN26: 0.37357415 | DU26: 29.271442
A27: agmll | BN27: 141.31635 | CZ27: 0.32198242 | DA27: 0.78378158 | DB27: 1.1874143 | DC27: 1.5925571 | DD27: 1.2480283 | DE27: 0.046170185 | DF27: 0.13559999 | DG27: 0.18283369 | DH27: 0.19339316 | DI27: 0.13896518 | DJ27: 0.013071076 | DK27: 0.016059855 | DL27: 0.045165062 | DM27: 0.10577161 | DN27: 0.12545317 | DU27: 147.4526
A28: afobe | BO28: 580.15588 | CZ28: 2.9228081 | DA28: 5.3369042 | DB28: 13.591556 | DC28: 34.682694 | DD28: 32.962728 | DE28: 0.50394281 | DF28: 2.1598576 | DG28: 4.3488146 | DH28: 4.0375209 | DI28: 4.6875275 | DJ28: 1.1359115e-05 | DK28: 0.88532665 | DL28: 0.68465487 | DM28: 1.0224212 | DN28: 8.9134268 | DU28: 696.89607
A29: aoapr | BP29: 37.508228 | DU29: 37.508228
A30: atext | BQ30: 146.05317 | DU30: 146.05317
A31: awood | BR31: 72.749181 | DU31: 72.749181
A32: apetr | BS32: 0.69963232 | DU32: 0.69963232
A33: achem | BU33: 111.65257 | DU33: 111.65257
A34: anmet | BV34: 98.698386 | DU34: 98.698386
A35: ametl | BW35: 75.890287 | DU35: 75.890287
A36: amach | BX36: 135.94789 | DU36: 135.94789
A37: aoman | BY37: 31.884649 | DU37: 31.884649
A38: aelec | BZ38: 220.60694 | DU38: 220.60694
A39: awatr | CA39: 75.773857 | DU39: 75.773857
A40: acons | CB40: 1864.4419 | DU40: 1864.4419
A41: atrad | CC41: 1409.6057 | DU41: 1409.6057
A42: atran | CD42: 1049.7073 | DU42: 1049.7073
A43: ahotl | CE43: 136.64748 | DU43: 136.64748
...

Sheet LES
A1: Households LES parametrization | R1: abecr | S1: cbecr
A2: DO NOT CHANGE ANYTHING UNLESS INSTRUCTED (BLACK cells should NOT be changed; color cells CAN be changed). Follow steps. | R2: aocrp | S2: cocrp
A4: STEP 0: classification
A6: SAM 4 letters | B6: cere | C6: gmll | D6: root | E6: puls | F6: vege | G6: frui | H6: fveg | I6: live | J6: fish | K6: meat | L6: fsea | M6: milk | N6: dair | O6: oils | P6: foil | Q6: fobe | R6: text | S6: elec | T6: watr | U6: real | V6: educ | W6: heal | X6: padm | Y6: becr | Z6: ocrp | AA6: fore | AB6: oapr | AC6: mine | AD6: mino | AE6: wood | AF6: petr | AG6: fert | AH6: chem | AI6: nmet | AJ6: metl | AK6: mach | AL6: oman | AM6: cons | AN6: hotl | AO6: rest | AP6: trad | AQ6: tran | AR6: comm | AS6: fsrv | AT6: bsrv | AU6: osrv
A7: SAM commodities | B7: ="c"&B6 -> ccere | C7: ="c"&C6 -> cgmll | D7: ="c"&D6 -> croot | E7: ="c"&E6 -> cpuls | F7: ="c"&F6 -> cvege | G7: ="c"&G6 -> cfrui | H7: ="c"&H6 -> cfveg | I7: ="c"&I6 -> clive | ... X7: ="c"&X6 -> cpadm | Y7: cbecr | Z7: ="c"&Z6 -> cocrp | AA7: ="c"&AA6 -> cfore | AB7: ="c"&AB6 -> coapr | AC7: ="c"&AC6 -> cmine | AD7: ="c"&AD6 -> cmino | AE7: ="c"&AE6 -> cwood | AF7: ="c"&AF6 -> cpetr | AG7: ="c"&AG6 -> cfert | ... AU7: ="c"&AU6 -> cosrv
A8: SAM activities | B8: ="a"&B6 -> acere | C8: ="a"&C6 -> agmll | D8: ="a"&D6 -> aroot | E8: ="a"&E6 -> apuls | F8: ="a"&F6 -> avege | G8: ="a"&G6 -> afrui | H8: ="a"&H6 -> afveg | I8: ="a"&I6 -> alive | ... X8: ="a"&X6 -> apadm | Y8: abecr | Z8: ="a"&Z6 -> aocrp | AA8: ="a"&AA6 -> afore | AB8: ="a"&AB6 -> aoapr | AC8: ="a"&AC6 -> amine | AD8: ="a"&AD6 -> amino | AE8: ="a"&AE6 -> awood | AF8: ="a"&AF6 -> apetr | AG8: ="a"&AG6 -> afert | ... AU8: ="a"&AU6 -> aosrv
A9: broad categories | B9: cereals | C9: cereals | D9: roots | E9: pulses | F9: vegetables | G9: fruits | H9: fruits | I9: fish-meat-egg | J9: fish-meat-egg | K9: fish-meat-egg | L9: fish-meat-egg | M9: diary | N9: diary | O9: fats & oils | P9: fats & oils | Q9: other food | R9: clothing and textile | S9: utilities | T9: utilities | U9: housing | V9: education, health and public | W9: education, health and public | X9: education, health and public | Y9: other ag | Z9: other ag | AA9: other ag | AB9: other ag | AC9: mining | AD9: mining | AE9: manufacturing | AF9: manufacturing | AG9: manufacturing | AH9: manufacturing | AI9: manufacturing | AJ9: manufacturing | AK9: manufacturing | AL9: manufacturing | AM9: contruction | AN9: hotels and restaurants | AO9: hotels and restaurants | AP9: trade, transport and comm | AQ9: trade, transport and comm | AR9: other services | AS9: other services | AT9: other services | AU9: other services
A10: given - residual categories | B10: =VLOOKUP(B9,$R$102:$S$122,2,FALSE) -> given | C10: =VLOOKUP(C9,$R$102:$S$122,2,FALSE) -> given | D10: =VLOOKUP(D9,$R$102:$S$122,2,FALSE) -> given | E10: =VLOOKUP(E9,$R$102:$S$122,2,FALSE) -> given | F10: =VLOOKUP(F9,$R$102:$S$122,2,FALSE) -> given | G10: =VLOOKUP(G9,$R$102:$S$122,2,FALSE) -> given | H10: =VLOOKUP(H9,$R$102:$S$122,2,FALSE) -> given | I10: =VLOOKUP(I9,$R$102:$S$122,2,FALSE) -> given | ... AU10: =VLOOKUP(AU9,$R$102:$S$122,2,FALSE) -> residual
A12: given=income elasticity WILL bew given
A13: residual = income elasticity WILL be calculated/calibrated as a residual
A15: STEP 1: calculate ABS - average budget shares (based on SAM).
A16: 20 groups - ABS | U16: SAM values
A17: given - residual categories | B17: caregory | C17: Rural farm | H17: Rural nonfarm | M17: Urban | R17: Total national | U17: Rural farm | Z17: Rural nonfarm | AE17: Urban | AJ17: total
C18: hhd-f1 | D18: hhd-f2 | E18: hhd-f3 | F18: hhd-f4 | G18: hhd-f5 | H18: hhd-n1 | I18: hhd-n2 | J18: hhd-n3 | K18: hhd-n4 | L18: hhd-n5 | M18: hhd-u1 | N18: hhd-u2 | O18: hhd-u3 | P18: hhd-u4 | Q18: hhd-u5 | U18: hhd-f1 | V18: hhd-f2 | W18: hhd-f3 | X18: hhd-f4 | Y18: hhd-f5 | Z18: hhd-n1 | AA18: hhd-n2 | AB18: hhd-n3 | AC18: hhd-n4 | AD18: hhd-n5 | AE18: hhd-u1 | AF18: hhd-u2 | AG18: hhd-u3 | AH18: hhd-u4 | AI18: hhd-u5
A19: =S102 -> given | B19: cereals | C19: =SUM(C49:C50) -> 5.8474237 | D19: =SUM(D49:D50) -> 5.8132634 | E19: =SUM(E49:E50) -> 5.1262812 | F19: =SUM(F49:F50) -> 4.4251416 | G19: =SUM(G49:G50) -> 3.2193942 | H19: =SUM(H49:H50) -> 6.4521064 | I19: =SUM(I49:I50) -> 5.0927933 | J19: =SUM(J49:J50) -> 5.7348475 | ... R19: =SUM(R49:R50) -> 3.1414299 | T19: cereals | U19: =SUM(U49:U50) -> 17.192658 | V19: =SUM(V49:V50) -> 25.319005 | W19: =SUM(W49:W50) -> 30.632765 | X19: =SUM(X49:X50) -> 38.02694 | Y19: =SUM(Y49:Y50) -> 30.630381 | Z19: =SUM(Z49:Z50) -> 3.6529017 | AA19: =SUM(AA49:AA50) -> 4.2992834 | AB19: =SUM(AB49:AB50) -> 5.8656167 | ... AJ19: =SUM(AJ49:AJ50) -> 221.71208
A20: =S103 -> given | B20: roots | C20: =SUM(C51:C51) -> 15.329137 | D20: =SUM(D51:D51) -> 15.412014 | E20: =SUM(E51:E51) -> 14.043551 | F20: =SUM(F51:F51) -> 11.054122 | G20: =SUM(G51:G51) -> 5.3288698 | H20: =SUM(H51:H51) -> 16.676685 | I20: =SUM(I51:I51) -> 15.477571 | J20: =SUM(J51:J51) -> 14.116111 | ... R20: =SUM(R51:R51) -> 6.7213637 | T20: roots | U20: =SUM(U51:U51) -> 45.070896 | V20: =SUM(V51:V51) -> 67.12527 | W20: =SUM(W51:W51) -> 83.919078 | X20: =SUM(X51:X51) -> 94.992311 | Y20: =SUM(Y51:Y51) -> 50.700631 | Z20: =SUM(Z51:Z51) -> 9.4416131 | AA20: =SUM(AA51:AA51) -> 13.066006 | AB20: =SUM(AB51:AB51) -> 14.437995 | ... AJ20: =SUM(AJ51:AJ51) -> 474.37238
A21: =S104 -> given | B21: pulses | C21: =C52 -> 2.6873199 | D21: =D52 -> 2.6837665 | E21: =E52 -> 2.4511214 | F21: =F52 -> 1.8965997 | G21: =G52 -> 1.1180208 | H21: =H52 -> 3.0950954 | I21: =I52 -> 2.6364508 | J21: =J52 -> 2.5257373 | ... R21: =R52 -> 1.2971815 | T21: pulses | U21: =U52 -> 7.9012871 | V21: =V52 -> 11.688839 | W21: =W52 -> 14.646997 | X21: =X52 -> 16.298208 | Y21: =Y52 -> 10.63722 | Z21: =Z52 -> 1.7523083 | AA21: =AA52 -> 2.2256645 | AB21: =AB52 -> 2.5833306 | ... AJ21: =AJ52 -> 91.550925
A22: =S105 -> given | B22: vegetables | C22: =SUM(C53:C53) -> 1.925068 | D22: =SUM(D53:D53) -> 1.5949273 | E22: =SUM(E53:E53) -> 1.2795649 | F22: =SUM(F53:F53) -> 0.91990221 | G22: =SUM(G53:G53) -> 0.62097707 | H22: =SUM(H53:H53) -> 2.1481701 | I22: =SUM(I53:I53) -> 1.4378946 | J22: =SUM(J53:J53) -> 1.2753145 | ... R22: =SUM(R53:R53) -> 0.81290826 | T22: vegetables | U22: =SUM(U53:U53) -> 5.6601058 | V22: =SUM(V53:V53) -> 6.9465237 | W22: =SUM(W53:W53) -> 7.6462077 | X22: =SUM(X53:X53) -> 7.9050725 | Y22: =SUM(Y53:Y53) -> 5.9081814 | Z22: =SUM(Z53:Z53) -> 1.2162004 | AA22: =SUM(AA53:AA53) -> 1.2138557 | AB22: =SUM(AB53:AB53) -> 1.304395 | ... AJ22: =SUM(AJ53:AJ53) -> 57.372468
A23: =S106 -> given | B23: fruits | C23: =SUM(C54:C55) -> 3.554369 | D23: =SUM(D54:D55) -> 4.3761805 | E23: =SUM(E54:E55) -> 4.7976149 | F23: =SUM(F54:F55) -> 5.197348 | G23: =SUM(G54:G55) -> 4.2769042 | H23: =SUM(H54:H55) -> 3.200744 | I23: =SUM(I54:I55) -> 4.5364174 | J23: =SUM(J54:J55) -> 4.7279048 | ... R23: =SUM(R54:R55) -> 3.9354202 | T23: fruits | U23: =SUM(U54:U55) -> 10.450594 | V23: =SUM(V54:V55) -> 19.059955 | W23: =SUM(W54:W55) -> 28.668777 | X23: =SUM(X54:X55) -> 44.662805 | Y23: =SUM(Y54:Y55) -> 40.691882 | Z23: =SUM(Z54:Z55) -> 1.8121219 | AA23: =SUM(AA54:AA55) -> 3.8295966 | AB23: =SUM(AB54:AB55) -> 4.8357131 | ... AJ23: =SUM(AJ54:AJ55) -> 277.74939
A24: =S107 -> given | B24: fish-meat-egg | C24: =SUM(C56:C59) -> 1.9432179 | D24: =SUM(D56:D59) -> 2.3761109 | E24: =SUM(E56:E59) -> 2.8162893 | F24: =SUM(F56:F59) -> 3.5330632 | G24: =SUM(G56:G59) -> 4.6605122 | H24: =SUM(H56:H59) -> 2.6306717 | I24: =SUM(I56:I59) -> 2.2145436 | J24: =SUM(J56:J59) -> 2.9292434 | ... R24: =SUM(R56:R59) -> 3.2139439 | T24: fish-meat-egg | U24: =SUM(U56:U59) -> 5.7134703 | V24: =SUM(V56:V59) -> 10.34888 | W24: =SUM(W56:W59) -> 16.829106 | X24: =SUM(X56:X59) -> 30.360967 | Y24: =SUM(Y56:Y59) -> 44.341655 | Z24: =SUM(Z56:Z59) -> 1.4893717 | AA24: =SUM(AA56:AA59) -> 1.8694948 | AB24: =SUM(AB56:AB59) -> 2.9960376 | ... AJ24: =SUM(AJ56:AJ59) -> 226.8299
A25: =S108 -> given | B25: diary | C25: =SUM(C60:C61) -> 0.45945972 | D25: =SUM(D60:D61) -> 1.2248358 | E25: =SUM(E60:E61) -> 1.5652824 | F25: =SUM(F60:F61) -> 2.5848027 | G25: =SUM(G60:G61) -> 2.8975604 | H25: =SUM(H60:H61) -> 0.57946833 | I25: =SUM(I60:I61) -> 1.1686335 | J25: =SUM(J60:J61) -> 1.5810084 | ... R25: =SUM(R60:R61) -> 1.8794543 | T25: diary | U25: =SUM(U60:U61) -> 1.3509084 | V25: =SUM(V60:V61) -> 5.3346325 | W25: =SUM(W60:W61) -> 9.3535502 | X25: =SUM(X60:X61) -> 22.212201 | Y25: =SUM(Y60:Y61) -> 27.568348 | Z25: =SUM(Z60:Z61) -> 0.32806973 | AA25: =SUM(AA60:AA61) -> 0.9865483 | AB25: =SUM(AB60:AB61) -> 1.6170595 | ... AJ25: =SUM(AJ60:AJ61) -> 132.64588
A26: =S109 -> given | B26: fats & oils | C26: =SUM(C62:C63) -> 1.4045161 | D26: =SUM(D62:D63) -> 1.745051 | E26: =SUM(E62:E63) -> 1.8566119 | F26: =SUM(F62:F63) -> 2.1156062 | G26: =SUM(G62:G63) -> 1.910915 | H26: =SUM(H62:H63) -> 1.6773444 | I26: =SUM(I62:I63) -> 1.9905489 | J26: =SUM(J62:J63) -> 1.7827506 | ... R26: =SUM(R62:R63) -> 1.6907854 | T26: fats & oils | U26: =SUM(U62:U63) -> 4.1295735 | V26: =SUM(V62:V63) -> 7.6003704 | W26: =SUM(W62:W63) -> 11.094428 | X26: =SUM(X62:X63) -> 18.180216 | Y26: =SUM(Y62:Y63) -> 18.181077 | Z26: =SUM(Z62:Z63) -> 0.94963936 | AA26: =SUM(AA62:AA63) -> 1.6804008 | AB26: =SUM(AB62:AB63) -> 1.8234018 | ... AJ26: =SUM(AJ62:AJ63) -> 119.33023
A27: =S110 -> given | B27: other food | C27: =SUM(C64:C64) -> 6.4552387 | D27: =SUM(D64:D64) -> 7.3966803 | E27: =SUM(E64:E64) -> 9.0900167 | F27: =SUM(F64:F64) -> 11.389314 | G27: =SUM(G64:G64) -> 12.54678 | H27: =SUM(H64:H64) -> 7.1906849 | I27: =SUM(I64:I64) -> 9.2224516 | J27: =SUM(J64:J64) -> 11.564234 | ... R27: =SUM(R64:R64) -> 9.1358558 | T27: other food | U27: =SUM(U64:U64) -> 18.979763 | V27: =SUM(V64:V64) -> 32.215397 | W27: =SUM(W64:W64) -> 54.318586 | X27: =SUM(X64:X64) -> 97.872741 | Y27: =SUM(Y64:Y64) -> 119.37422 | Z27: =SUM(Z64:Z64) -> 4.0710527 | AA27: =SUM(AA64:AA64) -> 7.7854982 | AB27: =SUM(AB64:AB64) -> 11.827928 | ... AJ27: =SUM(AJ64:AJ64) -> 644.77952
A28: =S111 -> given | B28: clothing and textile | C28: =SUM(C65:C65) -> 4.473367 | D28: =SUM(D65:D65) -> 5.089049 | E28: =SUM(E65:E65) -> 5.4129345 | F28: =SUM(F65:F65) -> 5.3812777 | G28: =SUM(G65:G65) -> 5.5308897 | H28: =SUM(H65:H65) -> 5.3625083 | I28: =SUM(I65:I65) -> 5.335442 | J28: =SUM(J65:J65) -> 5.4188607 | ... R28: =SUM(R65:R65) -> 5.0952858 | T28: clothing and textile | U28: =SUM(U65:U65) -> 13.152642 | V28: =SUM(V65:V65) -> 22.164772 | W28: =SUM(W65:W65) -> 32.3457 | X28: =SUM(X65:X65) -> 46.243384 | Y28: =SUM(Y65:Y65) -> 52.622715 | Z28: =SUM(Z65:Z65) -> 3.0360187 | AA28: =SUM(AA65:AA65) -> 4.5041249 | AB28: =SUM(AB65:AB65) -> 5.5424246 | ... AJ28: =SUM(AJ65:AJ65) -> 359.60899
A29: =S112 -> given | B29: utilities | C29: =SUM(C66:C67) -> 0.11269721 | D29: =SUM(D66:D67) -> 0.15064057 | E29: =SUM(E66:E67) -> 0.19010829 | F29: =SUM(F66:F67) -> 0.23118633 | G29: =SUM(G66:G67) -> 0.37166245 | H29: =SUM(H66:H67) -> 0.099453317 | I29: =SUM(I66:I67) -> 0.1684565 | J29: =SUM(J66:J67) -> 0.19589508 | ... R29: =SUM(R66:R67) -> 0.43415218 | T29: utilities | U29: =SUM(U66:U67) -> 0.33135355 | V29: =SUM(V66:V67) -> 0.6560978 | W29: =SUM(W66:W67) -> 1.136017 | X29: =SUM(X66:X67) -> 1.9866728 | Y29: =SUM(Y66:Y67) -> 3.5361196 | Z29: =SUM(Z66:Z67) -> 0.056306137 | AA29: =SUM(AA66:AA67) -> 0.14220924 | AB29: =SUM(AB66:AB67) -> 0.20036199 | ... AJ29: =SUM(AJ66:AJ67) -> 30.641074
A30: =S113 -> given | B30: housing | C30: =C68 -> 4.170447 | D30: =D68 -> 3.6597626 | E30: =E68 -> 3.489705 | F30: =F68 -> 3.6094547 | G30: =G68 -> 3.972662 | H30: =H68 -> 4.4520305 | I30: =I68 -> 3.9852434 | J30: =J68 -> 3.8932434 | ... R30: =R68 -> 6.866139 | T30: housing | U30: =U68 -> 12.261993 | V30: =V68 -> 15.939678 | W30: =W68 -> 20.85319 | X30: =X68 -> 31.017429 | Y30: =Y68 -> 37.797221 | Z30: =Z68 -> 2.5205458 | AA30: =AA68 -> 3.3643012 | AB30: =AB68 -> 3.9820193 | ... AJ30: =AJ68 -> 484.59015
A31: =S114 -> given | B31: education, health and public | C31: =SUM(C69:C71) -> 3.3034492 | D31: =SUM(D69:D71) -> 2.9859636 | E31: =SUM(E69:E71) -> 3.1352721 | F31: =SUM(F69:F71) -> 3.2908969 | G31: =SUM(G69:G71) -> 4.6220248 | H31: =SUM(H69:H71) -> 3.0223849 | I31: =SUM(I69:I71) -> 2.9427428 | J31: =SUM(J69:J71) -> 3.0357533 | ... R31: =SUM(R69:R71) -> 4.4868086 | T31: education, health and public | U31: =SUM(U69:U71) -> 9.7128372 | V31: =SUM(V69:V71) -> 13.005024 | W31: =SUM(W69:W71) -> 18.735229 | X31: =SUM(X69:X71) -> 28.27994 | Y31: =SUM(Y69:Y71) -> 43.975474 | Z31: =SUM(Z69:Z71) -> 1.7111427 | AA31: =SUM(AA69:AA71) -> 2.484233 | AB31: =SUM(AB69:AB71) -> 3.1049762 | ... AJ31: =SUM(AJ69:AJ71) -> 316.66462
A32: =S116 -> residual | B32: other ag | C32: =SUM(C72:C75) -> 27.274027 | D32: =SUM(D72:D75) -> 21.310065 | E32: =SUM(E72:E75) -> 16.943412 | F32: =SUM(F72:F75) -> 11.828871 | G32: =SUM(G72:G75) -> 5.8895526 | H32: =SUM(H72:H75) -> 21.965844 | I32: =SUM(I72:I75) -> 17.883887 | J32: =SUM(J72:J75) -> 13.42889 | ... R32: =SUM(R72:R75) -> 7.9257673 | T32: other ag | U32: =SUM(U72:U75) -> 80.191391 | V32: =SUM(V72:V75) -> 92.813556 | W32: =SUM(W72:W75) -> 101.24758 | X32: =SUM(X72:X75) -> 101.65003 | Y32: =SUM(Y72:Y75) -> 56.035152 | Z32: =SUM(Z72:Z75) -> 12.436104 | AA32: =SUM(AA72:AA75) -> 15.097393 | AB32: =SUM(AB72:AB75) -> 13.735103 | ... AJ32: =SUM(AJ72:AJ75) -> 559.37534
A33: =S117 -> residual | B33: mining | C33: =SUM(C76:C77) -> 0 | D33: =SUM(D76:D77) -> 0 | E33: =SUM(E76:E77) -> 0 | F33: =SUM(F76:F77) -> 0 | G33: =SUM(G76:G77) -> 0 | H33: =SUM(H76:H77) -> 0 | I33: =SUM(I76:I77) -> 0 | J33: =SUM(J76:J77) -> 0 | ... R33: =SUM(R76:R77) -> 0 | T33: mining | U33: =SUM(U76:U77) -> 0 | V33: =SUM(V76:V77) -> 0 | W33: =SUM(W76:W77) -> 0 | X33: =SUM(X76:X77) -> 0 | Y33: =SUM(Y76:Y77) -> 0 | Z33: =SUM(Z76:Z77) -> 0 | AA33: =SUM(AA76:AA77) -> 0 | AB33: =SUM(AB76:AB77) -> 0 | ... AJ33: =SUM(AJ76:AJ77) -> 0
A34: =S118 -> residual | B34: manufacturing | C34: =SUM(C78:C85) -> 4.9242994 | D34: =SUM(D78:D85) -> 5.4005383 | E34: =SUM(E78:E85) -> 6.3384538 | F34: =SUM(F78:F85) -> 6.6422132 | G34: =SUM(G78:G85) -> 8.4109984 | H34: =SUM(H78:H85) -> 5.3276082 | I34: =SUM(I78:I85) -> 6.2532297 | J34: =SUM(J78:J85) -> 5.8318313 | ... R34: =SUM(R78:R85) -> 7.9878791 | T34: manufacturing | U34: =SUM(U78:U85) -> 14.478478 | V34: =SUM(V78:V85) -> 23.521428 | W34: =SUM(W78:W85) -> 37.876262 | X34: =SUM(X78:X85) -> 57.079086 | Y34: =SUM(Y78:Y85) -> 80.025022 | Z34: =SUM(Z78:Z85) -> 3.0162598 | AA34: =SUM(AA78:AA85) -> 5.2789118 | AB34: =SUM(AB78:AB85) -> 5.9648119 | ... AJ34: =SUM(AJ78:AJ85) -> 563.75899
A35: =S119 -> residual | B35: contruction | C35: =C86 -> 0.50890552 | D35: =D86 -> 0.688258 | E35: =E86 -> 0.86413519 | F35: =F86 -> 1.2461045 | G35: =G86 -> 1.9506874 | H35: =H86 -> 0.49434015 | I35: =I86 -> 0.76934001 | J35: =J86 -> 1.1034575 | ... R35: =R86 -> 1.0665758 | T35: contruction | U35: =U86 -> 1.4962895 | V35: =V86 -> 2.9976292 | W35: =W86 -> 5.1637531 | X35: =X86 -> 10.708254 | Y35: =Y86 -> 18.559486 | Z35: =Z86 -> 0.27987387 | AA35: =AA86 -> 0.64946888 | AB35: =AB86 -> 1.1286191 | ... AJ35: =AJ86 -> 75.275511
A36: =S120 -> residual | B36: hotels and restaurants | C36: =SUM(C87,C88) -> 2.9215821 | D36: =SUM(D87,D88) -> 4.2814738 | E36: =SUM(E87,E88) -> 5.729958 | F36: =SUM(F87,F88) -> 6.3187424 | G36: =SUM(G87,G88) -> 7.5233544 | H36: =SUM(H87,H88) -> 3.7175808 | I36: =SUM(I87,I88) -> 5.0279259 | J36: =SUM(J87,J88) -> 6.2127334 | ... R36: =SUM(R87,R88) -> 6.0165137 | T36: hotels and restaurants | U36: =SUM(U87,U88) -> 8.5900672 | V36: =SUM(V87,V88) -> 18.647471 | W36: =SUM(W87,W88) -> 34.240115 | X36: =SUM(X87,X88) -> 54.299377 | Y36: =SUM(Y87,Y88) -> 71.579684 | Z36: =SUM(Z87,Z88) -> 2.1047324 | AA36: =SUM(AA87,AA88) -> 4.244523 | AB36: =SUM(AB87,AB88) -> 6.3543996 | ... AJ36: =SUM(AJ87,AJ88) -> 424.62632
A37: =S121 -> residual | B37: trade, transport and comm | C37: =SUM(C89:C91) -> 2.4208423 | D37: =SUM(D89:D91) -> 3.6943646 | E37: =SUM(E89:E91) -> 5.4691798 | F37: =SUM(F89:F91) -> 8.2407026 | G37: =SUM(G89:G91) -> 15.273503 | H37: =SUM(H89:H91) -> 1.7169841 | I37: =SUM(I89:I91) -> 3.2905148 | J37: =SUM(J89:J91) -> 5.0750963 | ... R37: =SUM(R89:R91) -> 16.325677 | T37: trade, transport and comm | U37: =SUM(U89:U91) -> 7.1177869 | V37: =SUM(V89:V91) -> 16.090384 | W37: =SUM(W89:W91) -> 32.681801 | X37: =SUM(X89:X91) -> 70.815518 | Y37: =SUM(Y89:Y91) -> 145.31716 | Z37: =SUM(Z89:Z91) -> 0.97208162 | AA37: =SUM(AA89:AA91) -> 2.7778186 | AB37: =SUM(AB89:AB91) -> 5.1908215 | ... AJ37: =SUM(AJ89:AJ91) -> 1152.2142
A38: =S122 -> residual | B38: other services | C38: =SUM(C92:C94) -> 10.284632 | D38: =SUM(D92:D94) -> 10.117055 | E38: =SUM(E92:E94) -> 9.4005074 | F38: =SUM(F92:F94) -> 10.094652 | G38: =SUM(G92:G94) -> 9.874732 | H38: =SUM(H92:H94) -> 10.190295 | I38: =SUM(I92:I94) -> 10.565913 | J38: =SUM(J92:J94) -> 9.5670872 | ... R38: =SUM(R92:R94) -> 11.966858 | T38: other services | U38: =SUM(U92:U94) -> 30.238987 | V38: =SUM(V92:V94) -> 44.063677 | W38: =SUM(W92:W94) -> 56.173964 | X38: =SUM(X92:X94) -> 86.747214 | Y38: =SUM(Y92:Y94) -> 93.951467 | Z38: =SUM(Z92:Z94) -> 5.7693016 | AA38: =SUM(AA92:AA94) -> 8.9196341 | AB38: =SUM(AB92:AB94) -> 9.7852413 | ... AJ38: =SUM(AJ92:AJ94) -> 844.58263
A39: Total food | C39: =SUM(C19:C27) -> 39.60575 | D39: =SUM(D19:D27) -> 42.62283 | E39: =SUM(E19:E27) -> 43.026333 | F39: =SUM(F19:F27) -> 43.115899 | G39: =SUM(G19:G27) -> 36.579933 | H39: =SUM(H19:H27) -> 43.650971 | I39: =SUM(I19:I27) -> 43.777305 | J39: =SUM(J19:J27) -> 46.237152 | ... R39: =SUM(R19:R27) -> 31.828343 | T39: Total food | U39: =SUM(U19:U27) -> 116.44926 | V39: =SUM(V19:V27) -> 185.63887 | W39: =SUM(W19:W27) -> 257.1095 | X39: =SUM(X19:X27) -> 370.51146 | Y39: =SUM(Y19:Y27) -> 348.03359 | Z39: =SUM(Z19:Z27) -> 24.713279 | AA39: =SUM(AA19:AA27) -> 36.956348 | AB39: =SUM(AB19:AB27) -> 47.291477 | ... AJ39: =SUM(AJ19:AJ27) -> 2246.3428
A40: Total nonfood | C40: =SUM(C28:C38) -> 60.39425 | D40: =SUM(D28:D38) -> 57.37717 | E40: =SUM(E28:E38) -> 56.973667 | F40: =SUM(F28:F38) -> 56.884101 | G40: =SUM(G28:G38) -> 63.420067 | H40: =SUM(H28:H38) -> 56.349029 | I40: =SUM(I28:I38) -> 56.222695 | J40: =SUM(J28:J38) -> 53.762848 | ... R40: =SUM(R28:R38) -> 68.171657 | T40: Total nonfood | U40: =SUM(U29:U38) -> 164.41918 | V40: =SUM(V29:V38) -> 227.73494 | W40: =SUM(W29:W38) -> 308.10791 | X40: =SUM(X29:X38) -> 442.58352 | Y40: =SUM(Y29:Y38) -> 550.77678 | Z40: =SUM(Z29:Z38) -> 28.866348 | AA40: =SUM(AA29:AA38) -> 42.958492 | AB40: =SUM(AB29:AB38) -> 49.446354 | ... AJ40: =SUM(AJ29:AJ38) -> 4451.7288
A41: Total given | C41: =SUM(C19:C31) -> 51.665711 | D41: =SUM(D19:D31) -> 54.508246 | E41: =SUM(E19:E31) -> 55.254353 | F41: =SUM(F19:F31) -> 55.628715 | G41: =SUM(G19:G31) -> 51.077172 | H41: =SUM(H19:H31) -> 56.587348 | I41: =SUM(I19:I31) -> 56.20919 | J41: =SUM(J19:J31) -> 58.780904 | ... R41: =SUM(R19:R31) -> 48.710729
A42: Total residual | C42: =SUM(C32:C38) -> 48.334289 | D42: =SUM(D32:D38) -> 45.491754 | E42: =SUM(E32:E38) -> 44.745647 | F42: =SUM(F32:F38) -> 44.371285 | G42: =SUM(G32:G38) -> 48.922828 | H42: =SUM(H32:H38) -> 43.412652 | I42: =SUM(I32:I38) -> 43.79081 | J42: =SUM(J32:J38) -> 41.219096 | ... R42: =SUM(R32:R38) -> 51.289271
A43: Total | C43: =C39+C40 -> 100 | D43: =D39+D40 -> 100 | E43: =E39+E40 -> 100 | F43: =F39+F40 -> 100 | G43: =G39+G40 -> 100 | H43: =H39+H40 -> 100 | I43: =I39+I40 -> 100 | J43: =J39+J40 -> 100 | ... R43: =R39+R40 -> 100 | T43: Total | U43: =U39+U40 -> 280.86844 | V43: =V39+V40 -> 413.37382 | W43: =W39+W40 -> 565.21741 | X43: =X39+X40 -> 813.09498 | Y43: =Y39+Y40 -> 898.81038 | Z43: =Z39+Z40 -> 53.579627 | AA43: =AA39+AA40 -> 79.91484 | AB43: =AB39+AB40 -> 96.737831 | ... AJ43: =AJ39+AJ40 -> 6698.0716
A46: ABS - disagg
...

Sheet Elasticities
A1: Factor and Trade Substitution Elasticities
A2: Instruction | B2: Enter elasticities if available.
B4: * | F4: *
A5: Trade elasticities (TRADELAS) | E5: Production elasticities (PRODELAS)
B6: Armington | C6: Transformation | F6: Factor substitution | J6: Assigned GTAP elasticities | M6: Original GTAP elasticities
B7: SIGMAQ | C7: SIGMAT | F7: PRODELAS | G7: PRODELAS2 | K7: Mapped | N7: Armington | O7: Region | P7: Factor
A8: ccere | B8: =K8 -> 1.3 | C8: =B8 -> 1.3 | E8: acere | F8: 0.5 | G8: 0.5 | J8: ccere | K8: =N10 -> 1.3 | M8: Paddy rice | N8: 5.05 | O8: 10.1 | P8: 0.24 | R8: =P8 -> 0.24 | S8: =R8 -> 0.24
A9: cpuls | B9: =K9 -> 1.85 | C9: =B9 -> 1.85 | E9: apuls | F9: 0.5 | G9: 0.5 | J9: cpuls | K9: =N11 -> 1.85 | M9: Wheat | N9: 4.45 | O9: 8.9 | P9: 0.24 | R9: =R8 -> 0.24 | S9: =R9 -> 0.24
A10: coils | B10: =K10 -> 2.45 | C10: =B10 -> 2.45 | E10: aoils | F10: 0.5 | G10: 0.5 | J10: coils | K10: =N12 -> 2.45 | M10: Cereal grains nec | N10: 1.3 | O10: 2.6 | P10: 0.24 | R10: =R9 -> 0.24 | S10: =R10 -> 0.24
A11: croot | B11: =K11 -> 1.85 | C11: =B11 -> 1.85 | E11: aroot | F11: 0.5 | G11: 0.5 | J11: croot | K11: =N11 -> 1.85 | M11: Vegetables, fruit, nuts | N11: 1.85 | O11: 3.7 | P11: 0.24 | R11: =R10 -> 0.24 | S11: =R11 -> 0.24
A12: cvege | B12: =K12 -> 1.85 | C12: =B12 -> 1.85 | E12: avege | F12: 0.5 | G12: 0.5 | J12: cvege | K12: =N11 -> 1.85 | M12: Oil seeds | N12: 2.45 | O12: 4.9 | P12: 0.24 | R12: =R11 -> 0.24 | S12: =R12 -> 0.24
A13: cfrui | B13: =K13 -> 1.85 | C13: =B13 -> 1.85 | E13: afrui | F13: 0.5 | G13: 0.5 | J13: cfrui | K13: =N11 -> 1.85 | M13: Sugar cane, sugar beet | N13: 2.7 | O13: 5.4 | P13: 0.24 | R13: =R12 -> 0.24 | S13: =R13 -> 0.24
A14: cbecr | B14: =K14 -> 3.25 | C14: =B14 -> 3.25 | E14: abecr | F14: 0.5 | G14: 0.5 | J14: cbecr | K14: =N15 -> 3.25 | M14: Plant-based fibers | N14: 2.5 | O14: 5 | P14: 0.24 | R14: =R13 -> 0.24 | S14: =R14 -> 0.24
A15: cocrp | B15: =K15 -> 3.25 | C15: =B15 -> 3.25 | E15: aocrp | F15: 0.5 | G15: 0.5 | J15: cocrp | K15: =N15 -> 3.25 | M15: Crops nec | N15: 3.25 | O15: 6.5 | P15: 0.24 | R15: =R14 -> 0.24 | S15: =R15 -> 0.24
A16: clive | B16: =K16 -> 2 | C16: =B16 -> 2 | E16: alive | F16: 0.5 | G16: 0.5 | J16: clive | K16: =N16 -> 2 | M16: Bovine cattle, sheep and goats, | N16: 2 | O16: 4 | P16: 0.24 | R16: =R15 -> 0.24 | S16: =R16 -> 0.24
A17: cmilk | B17: =K17 -> 3.65 | C17: =B17 -> 3.65 | E17: amilk | F17: 0.5 | G17: 0.5 | J17: cmilk | K17: =N18 -> 3.65 | M17: Animal products nec | N17: 1.3 | O17: 2.6 | P17: 0.24 | R17: =P20 -> 0.2 | S17: =R17 -> 0.2
A18: cfore | B18: =K18 -> 2.5 | C18: =B18 -> 2.5 | E18: afore | F18: 0.5 | G18: 0.5 | J18: cfore | K18: =N20 -> 2.5 | M18: Raw milk | N18: 3.65 | O18: 7.3 | P18: 0.24 | R18: =P21 -> 0.2 | S18: =R18 -> 0.2
A19: cfish | B19: =K19 -> 1.25 | C19: =B19 -> 1.25 | E19: afish | F19: 0.5 | G19: 0.5 | J19: cfish | K19: =N21 -> 1.25 | M19: Wool, silk-worm cocoons | N19: 6.45 | O19: 12.9 | P19: 0.24 | R19: =P23 -> 0.2 | S19: =R19 -> 0.2
A20: cmine | B20: =K20 -> 5.2 | C20: =B20 -> 5.2 | E20: amine | F20: 0.5 | G20: 0.5 | J20: cmine | K20: =N23 -> 5.2 | M20: Forestry | N20: 2.5 | O20: 5 | P20: 0.2 | R20: =R19 -> 0.2 | S20: =R20 -> 0.2
A21: cmino | B21: =K21 -> 0.9 | C21: =B21 -> 0.9 | E21: amino | F21: 0.5 | G21: 0.5 | J21: cmino | K21: =N25 -> 0.9 | M21: Fishing | N21: 1.25 | O21: 2.5 | P21: 0.2
A22: cgmll | B22: =K22 -> 2.6 | C22: =B22 -> 2.6 | E22: agmll | F22: =P26 -> 1.12 | G22: =F22 -> 1.12 | J22: cgmll | K22: =N30 -> 2.6 | M22: Coal | N22: 3.05 | O22: 6.1 | P22: 0.2
A23: cfoil | B23: =K23 -> 3.3 | C23: =B23 -> 3.3 | E23: afoil | F23: =F22 -> 1.12 | G23: =F23 -> 1.12 | J23: cfoil | K23: =N28 -> 3.3 | M23: Oil | N23: 5.2 | O23: 10.4 | P23: 0.2
A24: cfveg | B24: =K24 -> 3.65 | C24: =B24 -> 3.65 | E24: afveg | F24: =F23 -> 1.12 | G24: =F24 -> 1.12 | J24: cfveg | K24: =N29 -> 3.65 | M24: Gas | N24: 17.2 | O24: 34.4 | P24: 0.2
A25: cmeat | B25: =K25 -> 3.85 | C25: =B25 -> 3.85 | E25: ameat | F25: =F24 -> 1.12 | G25: =F25 -> 1.12 | J25: cmeat | K25: =N26 -> 3.85 | M25: Minerals nec | N25: 0.9 | O25: 1.8 | P25: 0.2
A26: cfsea | B26: =K26 -> 4.4 | C26: =B26 -> 4.4 | E26: afsea | F26: =F25 -> 1.12 | G26: =F26 -> 1.12 | J26: cfsea | K26: =N27 -> 4.4 | M26: Bovine meat prods | N26: 3.85 | O26: 7.7 | P26: 1.12
A27: cdair | B27: =K27 -> 3.3 | C27: =B27 -> 3.3 | E27: adair | F27: =F26 -> 1.12 | G27: =F27 -> 1.12 | J27: cdair | K27: =N28 -> 3.3 | M27: Meat products nec | N27: 4.4 | O27: 8.8 | P27: 1.12
A28: cfobe | B28: =K28 -> 2 | C28: =B28 -> 2 | E28: afobe | F28: =F27 -> 1.12 | G28: =F28 -> 1.12 | J28: cfobe | K28: =N32 -> 2 | M28: Vegetable oils and fats | N28: 3.3 | O28: 6.6 | P28: 1.12
A29: coapr | B29: =K29 -> 3.75 | C29: =B29 -> 3.75 | E29: aoapr | F29: =F28 -> 1.12 | G29: =F29 -> 1.12 | J29: coapr | K29: =N34 -> 3.75 | M29: Dairy products | N29: 3.65 | O29: 7.3 | P29: 1.12
A30: ctext | B30: 0.5 | C30: =K30 -> 3.75 | E30: atext | F30: =P34 -> 1.26 | G30: =F30 -> 1.26 | J30: ctext | K30: =N34 -> 3.75 | M30: Processed rice | N30: 2.6 | O30: 5.2 | P30: 1.12
A31: cwood | B31: 0.5 | C31: =K31 -> 3.4 | E31: awood | F31: =P37 -> 1.26 | G31: =F31 -> 1.26 | J31: cwood | K31: =N37 -> 3.4 | M31: Sugar | N31: 2.7 | O31: 5.4 | P31: 1.12
A32: cpetr | B32: 0.5 | C32: =K32 -> 2.1 | E32: apetr | F32: =P39 -> 1.26 | G32: =F32 -> 1.26 | J32: cpetr | K32: =N39 -> 2.1 | M32: Food products nec | N32: 2 | O32: 4 | P32: 1.12
A33: cfert | B33: 0.5 | C33: =K33 -> 3.3 | E33: afert | F33: =P40 -> 1.26 | G33: =F33 -> 1.26 | J33: cfert | K33: =N40 -> 3.3 | M33: Beverages and tobacco products | N33: 1.15 | O33: 2.3 | P33: 1.12
A34: cchem | B34: 0.5 | C34: =K34 -> 3.3 | E34: achem | F34: =F33 -> 1.26 | G34: =F34 -> 1.26 | J34: cchem | K34: =N40 -> 3.3 | M34: Textiles | N34: 3.75 | O34: 7.5 | P34: 1.26
A35: cnmet | B35: 0.5 | C35: =K35 -> 2.9 | E35: anmet | F35: =F34 -> 1.26 | G35: =F35 -> 1.26 | J35: cnmet | K35: =N41 -> 2.9 | M35: Wearing apparel | N35: 3.7 | O35: 7.4 | P35: 1.26
A36: cmetl | B36: 0.5 | C36: =K36 -> 2.95 | E36: ametl | F36: =F35 -> 1.26 | G36: =F36 -> 1.26 | J36: cmetl | K36: =N42 -> 2.95 | M36: Leather products | N36: 4.05 | O36: 8.1 | P36: 1.26
A37: cmach | B37: 0.5 | C37: =K37 -> 4.4 | E37: amach | F37: =F36 -> 1.26 | G37: =F37 -> 1.26 | J37: cmach | K37: =N47 -> 4.4 | M37: Wood products | N37: 3.4 | O37: 6.8 | P37: 1.26
A38: coman | B38: 0.5 | C38: =K38 -> 3.75 | E38: aoman | F38: =F37 -> 1.26 | G38: =F38 -> 1.26 | J38: coman | K38: =N49 -> 3.75 | M38: Paper products, publishing | N38: 2.95 | O38: 5.9 | P38: 1.26
A39: celec | B39: =K39 -> 2.8 | C39: =B39 -> 2.8 | E39: aelec | F39: =F38 -> 1.26 | G39: =F39 -> 1.26 | J39: celec | K39: =N50 -> 2.8 | M39: Petroleum, coal products | N39: 2.1 | O39: 4.2 | P39: 1.26
A40: cwatr | B40: =K40 -> 2.8 | C40: =B40 -> 2.8 | E40: awatr | F40: =F39 -> 1.26 | G40: =F40 -> 1.26 | J40: cwatr | K40: =N52 -> 2.8 | M40: Chemical, rubber, plastic products | N40: 3.3 | O40: 6.6 | P40: 1.26
A41: ccons | B41: =K41 -> 0.5 | C41: =B41 -> 0.5 | E41: acons | F41: =P54 -> 1.68 | G41: =F41 -> 1.68 | J41: ccons | K41: 0.5 | M41: Mineral products nec | N41: 2.9 | O41: 5.8 | P41: 1.26
...

Sheet Production
A1: Agricultural Production Quantities | I1: Agricultural Production Quantities
A2: Instruction | B2: Enter land area and quantity produced for crops and livestock (by region if necessary) | I2: Instruction | J2: Enter land area and quantity produced for crops and livestock (by region if necessary)
B4: * | C4: * | J4: * | K4: *
B5: Production | C5: Area | D5: Yield | J5: Production | K5: Area | L5: Yield
B6: 1000mt | C6: 1000ha | D6: mt/ha | J6: 1000mt | K6: 1000ha | L6: mt/ha
B7: x | C7: x | D7: x | J7: x | K7: x | L7: x
B8: prod | C8: area | D8: yield | J8: prod | K8: area | L8: yield
A9: acere | B9: =SUM(J9:J13) -> 733.171 | C9: =SUM(K9:K13) -> 567.26163 | D9: =IF(C9>0,B9/C9,0) -> 1.2924742 | I9: amaiz | J9: 421.218 | K9: 349.56498 | L9: 1.2049777
A10: apuls | B10: =J14 -> 499.651 | C10: =K14 -> 607.43577 | D10: =IF(C10>0,B10/C10,0) -> 0.82255775 | I10: asorg | J10: 159.626 | K10: 151.23928 | L10: 1.0554533
A11: aoils | B11: =SUM(J15:J16) -> 44.087 | C11: =SUM(K15:K16) -> 97.682345 | D11: =IF(C11>0,B11/C11,0) -> 0.45133028 | I11: arice | J11: 131.577 | K11: 38.139433 | L11: 3.4498939
A12: aroot | B12: =SUM(J17:J20) -> 3574.621 | C12: =SUM(K17:K20) -> 497.53017 | D12: =IF(C12>0,B12/C12,0) -> 7.1847321 | I12: awhea | J12: 15.687 | K12: 15.445794 | L12: 1.0156163
A13: avege | B13: =SUM(J21:J22) -> 350.505 | C13: =SUM(K21:K22) -> 99.028088 | D13: =IF(C13>0,B13/C13,0) -> 3.5394503 | I13: aocer | J13: 5.063 | K13: 12.872152 | L13: 0.39332972
A14: afrui | B14: =SUM(J26:J29) -> 1945.703 | C14: =SUM(K26:K29) -> 153.11818 | D14: =IF(C14>0,B14/C14,0) -> 12.707198 | I14: apuls | J14: 499.651 | K14: 607.43577 | L14: 0.82255775
A15: abecr | B15: =SUM(J23,J30:J32) -> 159.856 | C15: =SUM(K23,K30:K32) -> 46.048254 | D15: =IF(C15>0,B15/C15,0) -> 3.4714888 | I15: agnut | J15: 19.562 | K15: 43.003707 | L15: 0.45489102
A16: aocrp | B16: =SUM(J24:J25,J33:J35) -> 14.67 | C16: =SUM(K24:K25,K33:K35) -> 15.706496 | D16: =IF(C16>0,B16/C16,0) -> 0.93400844 | I16: aoils | J16: 24.525 | K16: 54.678638 | L16: 0.44852983
A17: alive | B17: =SUM(J36,J38:J41) -> 127.346 | C17: =SUM(K36,K38:K41) -> 0 | D17: =IF(C17>0,B17/C17,0) -> 0 | I17: acass | J17: 1181.825 | K17: 136.10452 | L17: 8.6832167
A18: amilk | B18: =J37 -> 252.479 | C18: =K37 -> 0 | D18: =IF(C18>0,B18/C18,0) -> 0 | I18: aipot | J18: 973.408 | K18: 108.12257 | L18: 9.0028194
I19: aspot | J19: 1247.584 | K19: 213.45783 | L19: 5.8446392
I20: aroot | J20: 171.804 | K20: 39.845251 | L20: 4.3117811
I21: aleaf | J21: 0 | K21: 0 | L21: 0
I22: avege | J22: 350.505 | K22: 99.028088 | L22: 3.5394503
I23: asugr | J23: 109.557 | K23: 7.72497 | L23: 14.182191
I24: atoba | J24: 4.903 | K24: 4.2869987 | L24: 1.1436906
I25: acott | J25: 0 | K25: 0 | L25: 0
I26: anuts | J26: 0 | K26: 0 | L26: 0
I27: abana | J27: 1046.993 | K27: 141.50247 | L27: 7.3991144
I28: aplan | J28: 820.917 | K28: 0
I29: afrui | J29: 77.793 | K29: 11.615701 | L29: 6.6972281
I30: ateal | J30: 31.068 | K30: 20.401918 | L30: 1.522798
I31: acoff | J31: 19.231 | K31: 17.921366 | L31: 1.0730767
I32: acoco | J32: 0 | K32: 0 | L32: 0
I33: aflwr | J33: 0 | K33: 0 | L33: 0
I34: arubb | J34: 0 | K34: 0 | L34: 0
I35: aocrp | J35: 9.767 | K35: 11.419497 | L35: 0.85529158
I36: acatt | J36: 34.575 | L36: 0
I37: amilk | J37: 252.479 | L37: 0
I38: apoul | J38: 19.064 | L38: 0
I39: aeggs | J39: 7.8 | L39: 0
I40: asmlr | J40: 36.661 | L40: 0
I41: aoliv | J41: 29.246 | L41: 0

Sheet Employment
A1: Labor Employment
A2: Instruction | B2: Enter either aggregate sector wages or employment numbers
C4: * | H4: * | I4: * | J4: * | K4: * | O4: * | P4: * | Q4: * | R4: * | S4: * | T4: * | U4: * | V4: *
A5: Aggregate sectors | C5: Mapping to subsectors | G5: Sectoral wages (WFBASE) | N5: Sectoral wages (WFBASE)
A6: AL | C6: AL | D6: A | H6: flab-n | I6: flab-p | J6: flab-s | K6: flab-t | O6: flab-rn | P6: flab-rp | Q6: flab-rs | R6: flab-rt | S6: flab-un | T6: flab-up | U6: flab-us | V6: flab-ut
A7: crp | C7: crp_cer | D7: acere | G7: crp | H7: =O7 -> 190.85595 | I7: =P7 -> 461.52328 | J7: =Q7 -> 1581.2528 | K7: =R7 -> 0 | N7: crp | O7: 190.85595 | P7: 461.52328 | Q7: 1581.2528 | R7: 0 | S7: 190.85595 | T7: 461.52328 | U7: 1581.2528 | V7: 0
A8: crp_cer | C8: crp_pul | D8: apuls | G8: crp_cer | H8: =O8 -> 190.85595 | I8: =P8 -> 461.52328 | J8: =Q8 -> 1581.2528 | K8: =R8 -> 0 | N8: crp_cer | O8: 190.85595 | P8: 461.52328 | Q8: 1581.2528 | R8: 0 | S8: 190.85595 | T8: 461.52328 | U8: 1581.2528 | V8: 0
A9: crp_pul | C9: crp_oil | D9: aoils | G9: crp_pul | H9: =O9 -> 190.85595 | I9: =P9 -> 461.52328 | J9: =Q9 -> 1581.2528 | K9: =R9 -> 0 | N9: crp_pul | O9: 190.85595 | P9: 461.52328 | Q9: 1581.2528 | R9: 0 | S9: 190.85595 | T9: 461.52328 | U9: 1581.2528 | V9: 0
A10: crp_oil | C10: crp_rts | D10: aroot | G10: crp_oil | H10: =O10 -> 190.85595 | I10: =P10 -> 461.52328 | J10: =Q10 -> 1581.2528 | K10: =R10 -> 0 | N10: crp_oil | O10: 190.85595 | P10: 461.52328 | Q10: 1581.2528 | R10: 0 | S10: 190.85595 | T10: 461.52328 | U10: 1581.2528 | V10: 0
A11: crp_rts | C11: crp_veg | D11: avege | G11: crp_rts | H11: =O11 -> 190.85595 | I11: =P11 -> 461.52328 | J11: =Q11 -> 1581.2528 | K11: =R11 -> 0 | N11: crp_rts | O11: 190.85595 | P11: 461.52328 | Q11: 1581.2528 | R11: 0 | S11: 190.85595 | T11: 461.52328 | U11: 1581.2528 | V11: 0
A12: crp_veg | C12: crp_fru | D12: afrui | G12: crp_veg | H12: =O12 -> 190.85595 | I12: =P12 -> 461.52328 | J12: =Q12 -> 1581.2528 | K12: =R12 -> 0 | N12: crp_veg | O12: 190.85595 | P12: 461.52328 | Q12: 1581.2528 | R12: 0 | S12: 190.85595 | T12: 461.52328 | U12: 1581.2528 | V12: 0
A13: crp_fru | C13: crp_exp | D13: abecr | G13: crp_fru | H13: =O13 -> 190.85595 | I13: =P13 -> 461.52328 | J13: =Q13 -> 1581.2528 | K13: =R13 -> 0 | N13: crp_fru | O13: 190.85595 | P13: 461.52328 | Q13: 1581.2528 | R13: 0 | S13: 190.85595 | T13: 461.52328 | U13: 1581.2528 | V13: 0
A14: crp_exp | C14: crp_exp | D14: aocrp | G14: crp_exp | H14: =O14 -> 190.85595 | I14: =P14 -> 461.52328 | J14: =Q14 -> 1581.2528 | K14: =R14 -> 0 | N14: crp_exp | O14: 190.85595 | P14: 461.52328 | Q14: 1581.2528 | R14: 0 | S14: 190.85595 | T14: 461.52328 | U14: 1581.2528 | V14: 0
A15: crp_oth | C15: liv | D15: alive | G15: crp_oth | H15: =O15 -> 190.85595 | I15: =P15 -> 461.52328 | J15: =Q15 -> 1581.2528 | K15: =R15 -> 0 | N15: crp_oth | O15: 190.85595 | P15: 461.52328 | Q15: 1581.2528 | R15: 0 | S15: 190.85595 | T15: 461.52328 | U15: 1581.2528 | V15: 0
A16: liv | C16: liv | D16: amilk | G16: liv | H16: =O16 -> 190.85595 | I16: =P16 -> 461.52328 | J16: =Q16 -> 1581.2528 | K16: =R16 -> 0 | N16: liv | O16: 190.85595 | P16: 461.52328 | Q16: 1581.2528 | R16: 0 | S16: 190.85595 | T16: 461.52328 | U16: 1581.2528 | V16: 0
A17: oag | C17: oag_for | D17: afore | G17: oag | H17: =O17 -> 190.85595 | I17: =P17 -> 461.52328 | J17: =Q17 -> 1581.2528 | K17: =R17 -> 0 | N17: oag | O17: 190.85595 | P17: 461.52328 | Q17: 1581.2528 | R17: 0 | S17: 190.85595 | T17: 461.52328 | U17: 1581.2528 | V17: 0
A18: oag_for | C18: oag_fsh | D18: afish | G18: oag_for | H18: =O18 -> 190.85595 | I18: =P18 -> 461.52328 | J18: =Q18 -> 1581.2528 | K18: =R18 -> 0 | N18: oag_for | O18: 190.85595 | P18: 461.52328 | Q18: 1581.2528 | R18: 0 | S18: 190.85595 | T18: 461.52328 | U18: 1581.2528 | V18: 0
... A41: osv | C41: trd | D41: atrad | G41: osv | H41: =O41 -> 530.76071 | I41: =P41 -> 1027.1356 | J41: =Q41 -> 1855.7703 | K41: =R41 -> 6206.9494 | N41: osv | O41: 530.76071 | P41: 1027.1356 | Q41: 1855.7703 | R41: 6206.9494 | S41: 530.76071 | T41: 1027.1356 | U41: 1855.7703 | V41: 6206.9494
C42: trn | D42: atran
C43: hfs | D43: ahotl
C44: hfs | D44: arest
C45: com | D45: acomm
C46: fsv | D46: afsrv
C47: rbs | D47: areal
C48: rbs | D48: absrv | H48: * | I48: * | J48: * | K48: * | O48: * | P48: * | Q48: * | R48: * | S48: * | T48: * | U48: * | V48: *
C49: pad | D49: apadm | G49: Sectoral employment (QFBASE) | N49: Sectoral employment (QFBASE)
C50: edu | D50: aeduc | H50: flab-n | I50: flab-p | J50: flab-s | K50: flab-t | O50: flab-rn | P50: flab-rp | Q50: flab-rs | R50: flab-rt | S50: flab-un | T50: flab-up | U50: flab-us | V50: flab-ut
C51: hsw | D51: aheal | G51: crp | H51: =O51 -> 0 | I51: =P51 -> 0 | J51: =Q51 -> 0 | K51: =R51 -> 0 | N51: crp
C52: osv | D52: aosrv | G52: crp_cer | H52: =O52 -> 0 | I52: =P52 -> 0 | J52: =Q52 -> 0 | K52: =R52 -> 0 | N52: crp_cer
G53: crp_pul | H53: =O53 -> 0 | I53: =P53 -> 0 | J53: =Q53 -> 0 | K53: =R53 -> 0 | N53: crp_pul
G54: crp_oil | H54: =O54 -> 0 | I54: =P54 -> 0 | J54: =Q54 -> 0 | K54: =R54 -> 0 | N54: crp_oil
G55: crp_rts | H55: =O55 -> 0 | I55: =P55 -> 0 | J55: =Q55 -> 0 | K55: =R55 -> 0 | N55: crp_rts
G56: crp_veg | H56: =O56 -> 0 | I56: =P56 -> 0 | J56: =Q56 -> 0 | K56: =R56 -> 0 | N56: crp_veg
G57: crp_fru | H57: =O57 -> 0 | I57: =P57 -> 0 | J57: =Q57 -> 0 | K57: =R57 -> 0 | N57: crp_fru
G58: crp_exp | H58: =O58 -> 0 | I58: =P58 -> 0 | J58: =Q58 -> 0 | K58: =R58 -> 0 | N58: crp_exp
G59: crp_oth | H59: =O59 -> 0 | I59: =P59 -> 0 | J59: =Q59 -> 0 | K59: =R59 -> 0 | N59: crp_oth
G60: liv | H60: =O60 -> 0 | I60: =P60 -> 0 | J60: =Q60 -> 0 | K60: =R60 -> 0 | N60: liv
G61: oag | H61: =O61 -> 0 | I61: =P61 -> 0 | J61: =Q61 -> 0 | K61: =R61 -> 0 | N61: oag
G62: oag_for | H62: =O62 -> 0 | I62: =P62 -> 0 | J62: =Q62 -> 0 | K62: =R62 -> 0 | N62: oag_for
G63: oag_fsh | H63: =O63 -> 0 | I63: =P63 -> 0 | J63: =Q63 -> 0 | K63: =R63 -> 0 | N63: oag_fsh
...

Sheet Population
A1: Household Population
A2: Instruction | B2: Enter number of people in each representative household group (sums to national population). | N2: Population (millions)
O3: National | P3: Urban | Q3: Rural
A4: thousand | B4: =SUM(B7:B21) -> 12794.4 | F4: Target population | H4: 12794.4 | I4: * | K4: * | N4: Survey | O4: =SUM(K7:K21)/1000 -> 11.717018 | P4: =SUM(K17:K21)/1000 -> 1.5451737 | Q4: =O4-P4 -> 10.171845
J5: Household survey data | N5: Base year | O5: =B4/1000 -> 12.7944 | P5: =P4/O4*O5 -> 1.6872526 | Q5: =O5-P5 -> 11.107147
B6: People | F6: Summary | G6: People | H6: Share | K6: People
