Workbook

Sheet Notes
A1: =C4&" "&C3&" RIAPA CGE Model" -> 2019 Malawi RIAPA CGE Model
A3: * | B3: Country | C3: Malawi
A4: * | B4: Base year | C4: 2019
A5: * | B5: Units | C5: Billions of kwacha
A10: Activities (a) and commodities (c) | E10: Factors (f) | I10: Households (hhd) | M10: Other accounts
A11: cere | B11: Cereals | E11: lab-n | F11: Labor - uneducated | I11: f1 | J11: Rural farm - quintile 1 | M11: trc | N11: Transaction costs
A12: puls | B12: Pulses | E12: lab-p | F12: Labor - primary | I12: f2 | J12: Rural farm - quintile 2 | M12: ent | N12: Enterprises
A13: oils | B13: Oilseeds | E13: lab-s | F13: Labor - secondary | I13: f3 | J13: Rural farm - quintile 3 | M13: gov | N13: Government
A14: root | B14: Roots and Tubers | E14: lab-t | F14: Labor - tertiary | I14: f4 | J14: Rural farm - quintile 4 | M14: atax | N14: Taxes - activity
A15: vege | B15: Vegetables | E15: lnd | F15: Land - agricultural crops | I15: f5 | J15: Rural farm - quintile 5 | M15: dtax | N15: Taxes - direct
A16: frui | B16: Fruits | E16: cap-c | F16: Capital - crops | I16: n1 | J16: Rural nonfarm - quintile 1 | M16: etax | N16: Taxes - export
A17: becr | B17: Beverage crops | E17: cap-l | F17: Capital - livestock | I17: n2 | J17: Rural nonfarm - quintile 2 | M17: ftax | N17: Taxes - factor
A18: ocrp | B18: Other non-food crops | E18: cap-m | F18: Capital - mining | I18: n3 | J18: Rural nonfarm - quintile 3 | M18: mtax | N18: Taxes - import
A19: live | B19: Livestock | E19: cap-o | F19: Capital - other | I19: n4 | J19: Rural nonfarm - quintile 4 | M19: stax | N19: Taxes - sales
A20: milk | B20: Raw milk | I20: n5 | J20: Rural nonfarm - quintile 5 | M20: s-i | N20: Savings-investment
A21: fore | B21: Forestry | I21: u1 | J21: Urban - quintile 1 | M21: dstk | N21: Change in stocks
A22: fish | B22: Fishery | I22: u2 | J22: Urban - quintile 2 | M22: row | N22: Rest of world
A23: mine | B23: Mining - energy | I23: u3 | J23: Urban - quintile 3 | M23: total | N23: Total
A24: mino | B24: Mining - other | I24: u4 | J24: Urban - quintile 4
A25: gmll | B25: Grain milling | I25: u5 | J25: Urban - quintile 5
A26: foil | B26: Fats and oils
A27: fveg | B27: Fruit and vegetable processing
A28: meat | B28: Meat processing
A29: fsea | B29: Fish and seafood processing
A30: dair | B30: Dairy
A31: fobe | B31: Other food and beverages
A32: oapr | B32: Other processing of ag products
A33: text | B33: Textiles
A34: wood | B34: Wood products
A35: petr | B35: Petroleum products
A36: fert | B36: Fertilizers and herbicides
A37: chem | B37: Chemicals
... A56: osrv | B56: Other services

Sheet Index
A1: GAMS GDX Index
A2: Instruction | B2: Do not alter this sheet.
D7: rdim | E7: cdim
A8: par | B8: nsam | C8: sam!a7 | D8: 1 | E8: 1
D15: rdim | E15: cdim
A16: dset | B16: ac | C16: sets!a7 | D16: 1
A17: dset | B17: rg | C17: sets!b7 | D17: 1
A18: dset | B18: a | C18: sets!c7 | D18: 1
A19: dset | B19: arg | C19: sets!d7 | D19: 1
A20: dset | B20: c | C20: sets!e7 | D20: 1
A21: dset | B21: f | C21: sets!f7 | D21: 1
A22: dset | B22: flab | C22: sets!g7 | D22: 1
A23: dset | B23: flnd | C23: sets!h7 | D23: 1
A24: dset | B24: fliv | C24: sets!i7 | D24: 1
A25: dset | B25: fcap | C25: sets!j7 | D25: 1
A26: dset | B26: ins | C26: sets!k7 | D26: 1
A27: dset | B27: insd | C27: sets!l7 | D27: 1
... A33: dset | B33: ctm | C33: sets!r7 | D33: 1
A34: set | B34: mac | C34: sets!t7 | D34: 2 | F34: values=nodata
A35: set | B35: marg | C35: sets!w7 | D35: 3 | F35: values=nodata
A36: dset | B36: eagr | C36: sets!aa7 | D36: 1
A37: dset | B37: emin | C37: sets!ab7 | D37: 1
A38: dset | B38: eman | C38: sets!ac7 | D38: 1
A39: dset | B39: eutl | C39: sets!ad7 | D39: 1
A40: dset | B40: econ | C40: sets!ae7 | D40: 1
A41: dset | B41: etrd | C41: sets!af7 | D41: 1
A42: dset | B42: etrc | C42: sets!ag7 | D42: 1
A43: dset | B43: ehfs | C43: sets!ah7 | D43: 1
A44: dset | B44: efbs | C44: sets!ai7 | D44: 1
A45: dset | B45: eres | C45: sets!aj7 | D45: 1
A46: dset | B46: egsv | C46: sets!ak7 | D46: 1
A47: dset | B47: eosv | C47: sets!al7 | D47: 1
... A53: dset | B53: cer | C53: adjust!f7 | D53: 1
A54: par | B54: sam | C54: sam!a7 | D54: 1 | E54: 1
A55: par | B55: leselas1 | C55: LES!b131 | D55: 1 | E55: 1
A56: par | B56: leselas2 | C56: LES!s131 | D56: 1 | E56: 1
A57: par | B57: FRISCH | C57: LES!C206 | E57: 1
A58: par | B58: tradelas | C58: elasticities!a7 | D58: 1 | E58: 1
A59: par | B59: prodelastab | C59: elasticities!e7 | D59: 1 | E59: 1
A60: par | B60: proddata | C60: production!a7 | D60: 1 | E60: 2
...

Sheet Sets
A1: Set Definitions
A2: Instruction | B2: Do not alter this sheet, unless you are adding new regions.
A4: Global set | B4: Regions | C4: Activities | E4: Commodities | F4: Factors | K4: Institutions | P4: Transaction costs | T4: Mapping activities to commodities | W4: Mapping activities to regions | AA4: Sectoral groups for employment calculations
C5: All | F5: All | G5: Labor | H5: Land | I5: Livestock | J5: Capital | K5: All | L5: Domestic | M5: Non-government | N5: Enterprises | O5: Households | P5: Domestic | Q5: Export | R5: Import | T5: MAC | W5: MARG | AA5: Agriculture | AB5: Industry
A6: AC | B6: RG | C6: A | D6: ARG | E6: C | F6: F | G6: FLAB | H6: FLND | I6: FLIV | J6: FCAP | K6: INS | L6: INSD | M6: INSDNG | N6: EN | O6: H | P6: CTD | Q6: CTE | R6: CTM | T6: A | U6: C | W6: ARG | X6: A | Y6: RG | AA6: EAGR | AB6: EMIN | AC6: EMAN | AD6: EUTL | AE6: ECON | AF6: ETRD | AG6: ETRC | AH6: EHFS | AI6: EFBS | AJ6: ERES | AK6: EGSV | AL6: EOSV
A7: acere | B7: x | C7: acere | D7: acere | E7: ccere | F7: flab-n | G7: flab-n | H7: flnd | I7: fcap-l | J7: fcap-c | K7: ent | L7: ent | M7: ent | N7: ent | O7: hhd-f1 | P7: trd | Q7: tre | R7: trm | T7: =C7 -> acere | U7: =E7 -> ccere | W7: =D7 -> acere | X7: =C7 -> acere | Y7: x | AA7: =W7 -> acere | AB7: =W19 -> amine | AC7: =W21 -> agmll | AD7: aelec | AE7: acons | AF7: atrad | AG7: atran | AH7: ahotl | AI7: afsrv | AJ7: areal | AK7: apadm | AL7: aosrv
A8: apuls | C8: apuls | D8: apuls | E8: cpuls | F8: flab-p | G8: flab-p | J8: fcap-m | K8: hhd-f1 | L8: hhd-f1 | M8: hhd-f1 | O8: hhd-f2 | T8: =C8 -> apuls | U8: =E8 -> cpuls | W8: =D8 -> apuls | X8: =C8 -> apuls | Y8: x | AA8: =W8 -> apuls | AB8: =W20 -> amino | AC8: =W22 -> afoil | AD8: awatr | AG8: acomm | AH8: arest | AJ8: absrv | AK8: aeduc
A9: aoils | C9: aoils | D9: aoils | E9: coils | F9: flab-s | G9: flab-s | J9: fcap-o | K9: hhd-f2 | L9: hhd-f2 | M9: hhd-f2 | O9: hhd-f3 | T9: =C9 -> aoils | U9: =E9 -> coils | W9: =D9 -> aoils | X9: =C9 -> aoils | Y9: x | AA9: =W9 -> aoils | AC9: =W23 -> afveg | AK9: aheal
A10: aroot | C10: aroot | D10: aroot | E10: croot | F10: flab-t | G10: flab-t | K10: hhd-f3 | L10: hhd-f3 | M10: hhd-f3 | O10: hhd-f4 | T10: =C10 -> aroot | U10: =E10 -> croot | W10: =D10 -> aroot | X10: =C10 -> aroot | Y10: x | AA10: =W10 -> aroot | AC10: =W24 -> ameat
A11: avege | C11: avege | D11: avege | E11: cvege | F11: flnd | K11: hhd-f4 | L11: hhd-f4 | M11: hhd-f4 | O11: hhd-f5 | T11: =C11 -> avege | U11: =E11 -> cvege | W11: =D11 -> avege | X11: =C11 -> avege | Y11: x | AA11: =W11 -> avege | AC11: =W25 -> afsea
A12: afrui | C12: afrui | D12: afrui | E12: cfrui | F12: fcap-c | K12: hhd-f5 | L12: hhd-f5 | M12: hhd-f5 | O12: hhd-n1 | T12: =C12 -> afrui | U12: =E12 -> cfrui | W12: =D12 -> afrui | X12: =C12 -> afrui | Y12: x | AA12: =W12 -> afrui | AC12: =W26 -> adair
A13: abecr | C13: abecr | D13: abecr | E13: cbecr | F13: fcap-l | K13: hhd-n1 | L13: hhd-n1 | M13: hhd-n1 | O13: hhd-n2 | T13: abecr | U13: cbecr | W13: abecr | X13: abecr | Y13: x | AA13: abecr | AC13: =W27 -> afobe
A14: aocrp | C14: aocrp | D14: aocrp | E14: cocrp | F14: fcap-m | K14: hhd-n2 | L14: hhd-n2 | M14: hhd-n2 | O14: hhd-n3 | T14: =C14 -> aocrp | U14: =E14 -> cocrp | W14: =D14 -> aocrp | X14: =C14 -> aocrp | Y14: x | AA14: =W14 -> aocrp | AC14: =W28 -> aoapr
A15: alive | C15: alive | D15: alive | E15: clive | F15: fcap-o | K15: hhd-n3 | L15: hhd-n3 | M15: hhd-n3 | O15: hhd-n4 | T15: =C15 -> alive | U15: =E15 -> clive | W15: =D15 -> alive | X15: =C15 -> alive | Y15: x | AA15: =W15 -> alive | AC15: =W29 -> atext
A16: amilk | C16: amilk | D16: amilk | E16: cmilk | K16: hhd-n4 | L16: hhd-n4 | M16: hhd-n4 | O16: hhd-n5 | T16: =C16 -> amilk | U16: =E16 -> cmilk | W16: =D16 -> amilk | X16: =C16 -> amilk | Y16: x | AA16: =W16 -> amilk | AC16: =W30 -> awood
A17: afore | C17: afore | D17: afore | E17: cfore | K17: hhd-n5 | L17: hhd-n5 | M17: hhd-n5 | O17: hhd-u1 | T17: =C17 -> afore | U17: =E17 -> cfore | W17: =D17 -> afore | X17: =C17 -> afore | Y17: x | AA17: =W17 -> afore | AC17: =W31 -> apetr
A18: afish | C18: afish | D18: afish | E18: cfish | K18: hhd-u1 | L18: hhd-u1 | M18: hhd-u1 | O18: hhd-u2 | T18: =C18 -> afish | U18: =E18 -> cfish | W18: =D18 -> afish | X18: =C18 -> afish | Y18: x | AA18: =W18 -> afish | AC18: =W32 -> afert
A19: amine | C19: amine | D19: amine | E19: cmine | K19: hhd-u2 | L19: hhd-u2 | M19: hhd-u2 | O19: hhd-u3 | T19: =C19 -> amine | U19: =E19 -> cmine | W19: =D19 -> amine | X19: =C19 -> amine | Y19: x | AC19: =W33 -> achem
A20: amino | C20: amino | D20: amino | E20: cmino | K20: hhd-u3 | L20: hhd-u3 | M20: hhd-u3 | O20: hhd-u4 | T20: =C20 -> amino | U20: =E20 -> cmino | W20: =D20 -> amino | X20: =C20 -> amino | Y20: x | AC20: =W34 -> anmet
A21: agmll | C21: agmll | D21: agmll | E21: cgmll | K21: hhd-u4 | L21: hhd-u4 | M21: hhd-u4 | O21: hhd-u5 | T21: =C21 -> agmll | U21: =E21 -> cgmll | W21: =D21 -> agmll | X21: =C21 -> agmll | Y21: x | AC21: =W35 -> ametl
A22: afoil | C22: afoil | D22: afoil | E22: cfoil | K22: hhd-u5 | L22: hhd-u5 | M22: hhd-u5 | T22: =C22 -> afoil | U22: =E22 -> cfoil | W22: =D22 -> afoil | X22: =C22 -> afoil | Y22: x | AC22: =W36 -> amach
A23: afveg | C23: afveg | D23: afveg | E23: cfveg | K23: gov | L23: gov | T23: =C23 -> afveg | U23: =E23 -> cfveg | W23: =D23 -> afveg | X23: =C23 -> afveg | Y23: x | AC23: =W37 -> aoman
A24: ameat | C24: ameat | D24: ameat | E24: cmeat | K24: row | T24: =C24 -> ameat | U24: =E24 -> cmeat | W24: =D24 -> ameat | X24: =C24 -> ameat | Y24: x
A25: afsea | C25: afsea | D25: afsea | E25: cfsea | T25: =C25 -> afsea | U25: =E25 -> cfsea | W25: =D25 -> afsea | X25: =C25 -> afsea | Y25: x
A26: adair | C26: adair | D26: adair | E26: cdair | T26: =C26 -> adair | U26: =E26 -> cdair | W26: =D26 -> adair | X26: =C26 -> adair | Y26: x
A27: afobe | C27: afobe | D27: afobe | E27: cfobe | T27: =C27 -> afobe | U27: =E27 -> cfobe | W27: =D27 -> afobe | X27: =C27 -> afobe | Y27: x
A28: aoapr | C28: aoapr | D28: aoapr | E28: coapr | T28: =C28 -> aoapr | U28: =E28 -> coapr | W28: =D28 -> aoapr | X28: =C28 -> aoapr | Y28: x
A29: atext | C29: atext | D29: atext | E29: ctext | T29: =C29 -> atext | U29: =E29 -> ctext | W29: =D29 -> atext | X29: =C29 -> atext | Y29: x
A30: awood | C30: awood | D30: awood | E30: cwood | T30: =C30 -> awood | U30: =E30 -> cwood | W30: =D30 -> awood | X30: =C30 -> awood | Y30: x
A31: apetr | C31: apetr | D31: apetr | E31: cpetr | T31: =C31 -> apetr | U31: =E31 -> cpetr | W31: =D31 -> apetr | X31: =C31 -> apetr | Y31: x
A32: afert | C32: afert | D32: afert | E32: cfert | T32: =C32 -> afert | U32: =E32 -> cfert | W32: =D32 -> afert | X32: =C32 -> afert | Y32: x
A33: achem | C33: achem | D33: achem | E33: cchem | T33: =C33 -> achem | U33: =E33 -> cchem | W33: =D33 -> achem | X33: =C33 -> achem | Y33: x
A34: anmet | C34: anmet | D34: anmet | E34: cnmet | T34: =C34 -> anmet | U34: =E34 -> cnmet | W34: =D34 -> anmet | X34: =C34 -> anmet | Y34: x
A35: ametl | C35: ametl | D35: ametl | E35: cmetl | T35: =C35 -> ametl | U35: =E35 -> cmetl | W35: =D35 -> ametl | X35: =C35 -> ametl | Y35: x
A36: amach | C36: amach | D36: amach | E36: cmach | T36: =C36 -> amach | U36: =E36 -> cmach | W36: =D36 -> amach | X36: =C36 -> amach | Y36: x
... A52: aosrv | C52: aosrv | D52: aosrv | E52: cosrv | T52: =C52 -> aosrv | U52: =E52 -> cosrv | W52: =D52 -> aosrv | X52: =C52 -> aosrv | Y52: x
A53: ccere
A54: cpuls
A55: coils
A56: croot
...

Sheet Adjust
A1: Adjustments to SAM Trade Flows
A3: * | B3: * | C3: * | D3: * | E3: * | F3: *
A4: Remove small trade shares | C4: Re-exports | D4: Net out trade | F4: Perfect substitutes
A5: Exports | B5: Imports | D5: Exports | E5: Imports | F5: Exports
A6: REMEXP | B6: REMIMP | C6: REEXPORT | D6: NETEXPS | E6: NETIMPS | F6: CER | I6: VA | J6: EXP | K6: IMP | L6: VAshr | M6: PRDshr | N6: EMPshr | O6: EXPshr | P6: EXP-OUTshr | Q6: IMPshr | R6: IMP-DEMshr | S6: DEM | T6: OUT
A7: cvege | B7: croot | D7: cmetl | E7: cpuls | H7: ccere | I7: 0.68165565 | K7: 0.05015769 | L7: 6.5800251 | M7: 4.9920698 | N7: 27.753459 | Q7: 1.4184436 | R7: 4.0289023 | S7: 1.2449468 | T7: 1.0181784
A8: cfore | B8: clive | D8: ccere | E8: coils | H8: cpuls | I8: 0.22891709 | J8: 0.080288572 | L8: 2.2097378 | M8: 1.2629201 | N8: 6.7706757 | O8: 9.1414718 | P8: 31.169843 | S8: 0.20385368 | T8: 0.25758414
A9: crest | B9: cfish | D9: croot | E9: cvege | H9: coils | I9: 0.18804362 | J9: 0.11447423 | L9: 1.8151859 | M9: 1.0437559 | N9: 5.8513376 | O9: 12.464859 | P9: 53.773162 | S9: 0.10822985 | T9: 0.21288358
A10: cfsrv | B10: cmeat | D10: clive | E10: cbecr | H10: croot | I10: 0.25014028 | L10: 2.4146053 | M10: 1.3481319 | N10: 10.603419 | S10: 0.34072197 | T10: 0.27496386
B11: cheal | D11: cfish | E11: cfore | H11: cvege | I11: 0.40195429 | L11: 3.8800666 | M11: 2.0232013 | N11: 14.50321 | S11: 0.46673947 | T11: 0.41265046
B12: creal | D12: cgmll | E12: cocrp | H12: cfrui | I12: 0.13262804 | J12: 0.018113531 | K12: 0.0032240588 | L12: 1.2802591 | M12: 0.71193449 | N12: 4.7898976 | O12: 2.0753095 | P12: 12.474405 | Q12: 0.090751795 | R12: 2.1450687 | S12: 0.15030096 | T12: 0.14520556
D13: cfoil | E13: cmino | H13: cbecr | I13: 0.10730854 | J13: 0.045907101 | L13: 1.0358498 | M13: 1.0280156 | N13: 3.4068211 | O13: 5.3644092 | P13: 21.894597 | S13: 0.19328398 | T13: 0.2096732
D14: cmeat | E14: cfveg | H14: cocrp | I14: 0.18532382 | J14: 0.13896136 | L14: 1.7889317 | M14: 1.4681891 | N14: 6.0517694 | O14: 15.702465 | P14: 46.405432 | S14: 0.18298201 | T14: 0.29945063
D15: cfsea | E15: cfobe | H15: clive | I15: 0.17424401 | L15: 1.6819782 | M15: 2.8208919 | N15: 2.7913141 | S15: 0.60998449 | T15: 0.57534675
D16: cdair | E16: coapr | H16: cmilk | I16: 0.018823242 | L16: 0.18170084 | M16: 0.18634842 | N16: 0.31604142 | S16: 0.039423396 | T16: 0.038007468
D17: ceduc | E17: chotl | H17: cfore | I17: 0.014431419 | L17: 0.13930656 | M17: 0.13915377 | N17: 0.20190854 | S17: 0.028447426 | T17: 0.028381687
D18: cheal | E18: crest | H18: cfish | I18: 0.15129692 | L18: 1.4604698 | M18: 1.2623269 | N18: 3.0276434 | S18: 0.25767047 | T18: 0.25746315
D19: cbsrv | E19: ccomm | H19: cmine | I19: 0.035168195 | K19: 0.0027604343 | L19: 0.33947874 | M19: 0.37499927 | N19: 0.078480388 | Q19: 0.089772736 | R19: 3.4159234 | S19: 0.080810776 | T19: 0.076484537
D20: cpadm | E20: cfsrv | H20: cmino | I20: 0.045593835 | J20: 0.014363522 | L20: 0.4401175 | M20: 0.27971279 | N20: 0.10563807 | O20: 1.4663199 | P20: 25.177082 | S20: 0.043926373 | T20: 0.057049987
D21: cosrv | H21: cgmll | I21: 0.11606797 | K21: 0.019142336 | L21: 1.1204046 | M21: 3.8440089 | N21: 0.20075546 | Q21: 0.50242551 | R21: 2.0508595 | S21: 0.93338115 | T21: 0.78402085
D22: ctext | H22: cfoil | I22: 0.11360182 | K22: 0.047548422 | L22: 1.0965989 | M22: 1.3340414 | N22: 0.29388646 | Q22: 1.2611177 | R22: 12.956782 | S22: 0.3669771 | T22: 0.27208998
D23: cwood | H23: cfveg | I23: 0.0035630376 | J23: 0.0014947948 | L23: 0.034394019 | M23: 0.048954414 | N23: 0.0093555661 | O23: 0.16947121 | P23: 14.970851 | S23: 0.0093500965 | T23: 0.0099847014
D24: cchem | H24: cmeat | I24: 0.086063682 | L24: 0.83077312 | M24: 1.9817982 | N24: 0.095677122 | S24: 0.4891597 | T24: 0.4042059
D25: ctran | H25: cfsea | I25: 0.090677562 | K25: 0.019182631 | L25: 0.87531092 | M25: 1.0426581 | N25: 0.098534705 | Q25: 0.5061688 | R25: 6.9038959 | S25: 0.27785226 | T25: 0.21265968
H26: cdair | I26: 0.012005729 | K26: 0.012477905 | L26: 0.11589136 | M26: 0.10953571 | N26: 0.03219301 | Q26: 0.34368903 | R26: 33.155588 | S26: 0.037634393 | T26: 0.022340812
H27: cfobe | I27: 0.24047385 | J27: 0.084616745 | L27: 2.3212952 | M27: 2.5518768 | N27: 0.5581942 | O27: 11.413242 | P27: 16.257486 | S27: 0.59338998 | T27: 0.52047866
H28: coapr | I28: 0.17722806 | J28: 0.26937567 | L28: 1.7107833 | M28: 2.502254 | N28: 0.42152433 | O28: 37.387597 | P28: 52.781746 | S28: 0.33758647 | T28: 0.51035764
H29: ctext | I29: 0.046368541 | K29: 0.036774305 | L29: 0.44759574 | M29: 0.77152461 | N29: 0.11005246 | Q29: 0.5429167 | R29: 14.826841 | S29: 0.24802522 | T29: 0.15735952
H30: cwood | I30: 0.043192012 | K30: 0.24909811 | L30: 0.41693269 | M30: 0.41371522 | N30: 0.081638307 | Q30: 6.5498592 | R30: 71.616252 | S30: 0.34782343 | T30: 0.084381011
H31: cpetr | I31: 0.0059843487 | K31: 0.55720339 | L31: 0.057766945 | M31: 0.087224169 | N31: 0.015805336 | Q31: 14.438869 | R31: 96.167268 | S31: 0.57941065 | T31: 0.017790169
H32: cfert | I32: 0.066975714 | K32: 0.10051038 | L32: 0.64651687 | M32: 0.47702744 | N32: 0.018180432 | Q32: 2.8783506 | R32: 47.130043 | S32: 0.21326179 | T32: 0.097294119
H33: cchem | I33: 0.18568323 | K33: 0.35864543 | L33: 1.7924011 | M33: 1.6530691 | N33: 0.12665633 | Q33: 10.419351 | R33: 48.799724 | S33: 0.73493333 | T33: 0.33715858
H34: cnmet | I34: 0.012280095 | K34: 0.14931843 | L34: 0.11853982 | M34: 0.13006002 | N34: 0.0079594718 | Q34: 4.1098642 | R34: 83.19572 | S34: 0.17947849 | T34: 0.026526934
H35: cmetl | I35: 0.029504287 | K35: 0.40363228 | L35: 0.28480501 | M35: 0.24032248 | N35: 0.038321644 | Q35: 11.285239 | R35: 87.917668 | S35: 0.45910257 | T35: 0.049015971
H36: cmach | I36: 0.0062444288 | K36: 1.4378297 | L36: 0.0602775 | M36: 0.099632821 | N36: 0.0063812819 | Q36: 35.374966 | R36: 98.183687 | S36: 1.4644283 | T36: 0.020321027
H37: coman | I37: 0.035205294 | K37: 0.10879408 | L37: 0.33983687 | M37: 0.52745383 | N37: 0.091219985 | Q37: 2.7020852 | R37: 44.536784 | S37: 0.24427915 | T37: 0.10757904
H38: celec | I38: 0.16176708 | L38: 1.5615384 | M38: 1.628627 | N38: 0.012196752 | S38: 0.36428577 | T38: 0.33217341
H39: cwatr | I39: 0.17564306 | L39: 1.6954833 | M39: 1.1129636 | N39: 0.041385104 | S39: 0.24981394 | T39: 0.22699912
H40: ccons | I40: 0.35294432 | L40: 3.4069732 | M40: 10.725134 | N40: 0.86321855 | S40: 2.1874894 | T40: 2.1874894
H41: ctrad | I41: 1.3930216 | L41: 13.446844 | M41: 11.190746 | N41: 4.217927 | S41: 2.2824552 | T41: 2.2824552
...

Sheet SAM
A1: Nexus Social Accounting Matrix
A2: Instruction | B2: Do not alter this sheet. This data is exported from x1aggregate.gms and x1aggregate.xlsx files, which aggregates the original SAM into the standard Nexus SAM structure.
B5: =B105/SUM(B101:B109) -> 0.43618734 | C5: =C105/SUM(C101:C109) -> 0.48406848 | D5: =D105/SUM(D101:D109) -> 0.44663715 | E5: =E105/SUM(E101:E109) -> 0.38977911 | F5: =F105/SUM(F101:F109) -> 0.40192869 | G5: =G105/SUM(G101:G109) -> 0.2157556 | H5: =H105/SUM(H101:H109) -> 0.30448031 | I5: =I105/SUM(I101:I109) -> 0.44286862 | J5: =SUM(B105:I105)/SUM(B101:I109) -> 0.40878364
B7: acere | C7: apuls | D7: aoils | E7: aroot | F7: avege | G7: abecr | H7: aocrp | I7: afrui | J7: alive | K7: amilk | L7: afore | M7: afish | N7: amine | O7: amino | P7: ameat | Q7: afsea | R7: afveg | S7: afoil | T7: adair | U7: agmll | V7: afobe | W7: aoapr | X7: atext | Y7: awood | Z7: apetr | AA7: afert | AB7: achem | AC7: anmet | AD7: ametl | AE7: amach | AF7: aoman | AG7: aelec | AH7: awatr | AI7: acons | AJ7: atrad | AK7: atran | AL7: ahotl | AM7: arest | AN7: acomm | AO7: afsrv | AP7: areal | AQ7: absrv | AR7: apadm | AS7: aeduc | AT7: aheal | AU7: aosrv | AV7: ccere | AW7: cpuls | AX7: coils | AY7: croot | AZ7: cvege | BA7: cbecr | BB7: cocrp | BC7: cfrui | BD7: clive | BE7: cmilk | BF7: cfore | BG7: cfish | BH7: cmine | BI7: cmino | BJ7: cmeat | BK7: cfsea | BL7: cfveg | BM7: cfoil | BN7: cdair | BO7: cgmll | BP7: cfobe | BQ7: coapr | BR7: ctext | BS7: cwood | BT7: cpetr | BU7: cfert | BV7: cchem | BW7: cnmet | BX7: cmetl | BY7: cmach | BZ7: coman | CA7: celec | CB7: cwatr | CC7: ccons | CD7: ctrad | CE7: ctran | CF7: chotl | CG7: crest | CH7: ccomm | CI7: cfsrv | CJ7: creal | CK7: cbsrv | CL7: cpadm | CM7: ceduc | CN7: cheal | CO7: cosrv | CP7: trc | CQ7: flab-n | CR7: flab-p | CS7: flab-s | CT7: flab-t | CU7: flnd | CV7: fcap-c | CW7: fcap-l | CX7: fcap-m | CY7: fcap-o | CZ7: ent | DA7: hhd-f1 | DB7: hhd-f2 | DC7: hhd-f3 | DD7: hhd-f4 | DE7: hhd-f5 | DF7: hhd-n1 | DG7: hhd-n2 | DH7: hhd-n3 | DI7: hhd-n4 | DJ7: hhd-n5 | DK7: hhd-u1 | DL7: hhd-u2 | DM7: hhd-u3 | DN7: hhd-u4 | DO7: hhd-u5 | DP7: gov | DQ7: dtax | DR7: mtax | DS7: stax | DT7: s-i | DU7: row | DV7: total
A8: acere | AV8: 624.2428 | DA8: 12.140448 | DB8: 19.572699 | DC8: 28.176981 | DD8: 31.430103 | DE8: 37.282055 | DK8: 0.04464363 | DL8: 0.099577616 | DM8: 0.59405598 | DN8: 1.4758956 | DO8: 4.0334632 | DV8: 759.09272
A9: apuls | AW9: 161.65023 | DA9: 2.1351119 | DB9: 4.2280476 | DC9: 5.7866884 | DD9: 7.3859267 | DE9: 9.9569551 | DM9: 0.012187296 | DN9: 0.36409442 | DO9: 0.52003646 | DV9: 192.03928
A10: aoils | AX10: 125.96792 | DA10: 1.0250403 | DB10: 2.3928904 | DC10: 4.9304051 | DD10: 9.8028385 | DE10: 13.308043 | DM10: 0.036369854 | DN10: 0.29373515 | DO10: 0.95598236 | DV10: 158.71322
A11: aroot | AY11: 142.52396 | DA11: 4.7708805 | DB11: 6.9207493 | DC11: 10.486407 | DD11: 17.749953 | DE11: 21.441577 | DK11: 0.0047318941 | DL11: 0.068042602 | DM11: 0.19389883 | DN11: 0.30654053 | DO11: 0.52981221 | DV11: 204.99655
A12: avege | AZ12: 223.33712 | DA12: 10.699985 | DB12: 15.204556 | DC12: 18.111845 | DD12: 20.104999 | DE12: 17.775067 | DK12: 0.1127455 | DL12: 0.20580061 | DM12: 0.3600205 | DN12: 0.63307972 | DO12: 1.1022016 | DV12: 307.64742
A13: abecr | BA13: 146.64982 | DA13: 0.29836823 | DB13: 0.63195932 | DC13: 0.86190453 | DD13: 1.6289018 | DE13: 5.3411283 | DM13: 0.014637914 | DN13: 0.032223984 | DO13: 0.86081409 | DV13: 156.31976
A14: aocrp | BB14: 223.20082 | DB14: 0.0032235539 | DD14: 0.0013444636 | DE14: 0.0097687794 | DO14: 0.037270125 | DV14: 223.25242
A15: afrui | BC15: 82.644538 | DA15: 1.519495 | DB15: 2.1157104 | DC15: 4.3588438 | DD15: 5.4665419 | DE15: 10.236394 | DL15: 0.030084525 | DM15: 0.072296234 | DN15: 0.22241168 | DO15: 1.5902418 | DV15: 108.25656
A16: alive | BD16: 252.18407 | DA16: 4.0306935 | DB16: 13.653222 | DC16: 22.757917 | DD16: 41.41015 | DE16: 88.914667 | DL16: 0.14509513 | DM16: 0.41375178 | DN16: 1.3006383 | DO16: 4.1338071 | DV16: 428.94401
A17: amilk | BE17: 24.992526 | DA17: 0.0043846467 | DB17: 0.11092434 | DC17: 0.36478232 | DD17: 0.85900255 | DE17: 1.8604905 | DO17: 0.14397703 | DV17: 28.336088
A18: afore | BF18: 21.093185 | DA18: 0.0063761334 | DB18: 0.0080537677 | DC18: 0.0084267673 | DD18: 0.01577628 | DE18: 0.013916296 | DK18: 0.00013595168 | DL18: 0.0003936995 | DM18: 0.00033621259 | DN18: 0.00071868226 | DO18: 0.012363638 | DV18: 21.159683
A19: afish | BG19: 188.18741 | DA19: 0.2037645 | DB19: 0.2729338 | DC19: 0.34692581 | DD19: 1.0521477 | DE19: 1.588914 | DO19: 0.29698475 | DV19: 191.94908
A20: amine | BH20: 57.022282 | DV20: 57.022282
A21: amino | BI21: 42.533047 | DV21: 42.533047
A22: ameat | BJ22: 301.35167 | DV22: 301.35167
A23: afsea | BK23: 158.5463 | DV23: 158.5463
A24: afveg | BL24: 7.4439943 | DV24: 7.4439943
A25: afoil | BM25: 202.85396 | DV25: 202.85396
A26: adair | BN26: 16.655969 | DV26: 16.655969
A27: agmll | BO27: 584.5189 | DV27: 584.5189
A28: afobe | BP28: 334.34196 | DA28: 1.2761445 | DB28: 4.6227172 | DC28: 9.7417227 | DD28: 14.193873 | DE28: 20.060219 | DK28: 0.0011066193 | DL28: 0.11586351 | DM28: 0.080437461 | DN28: 0.66150583 | DO28: 2.9421102 | DV28: 388.03766
A29: aoapr | BQ29: 380.49204 | DV29: 380.49204
A30: atext | BR30: 117.31781 | DV30: 117.31781
A31: awood | BS31: 62.909419 | DV31: 62.909419
A32: apetr | BT32: 13.263282 | DV32: 13.263282
A33: afert | BU33: 72.536657 | DV33: 72.536657
A34: achem | BV34: 251.36521 | DV34: 251.36521
A35: anmet | BW35: 19.77689 | DV35: 19.77689
A36: ametl | BX36: 36.543367 | DV36: 36.543367
A37: amach | BY37: 15.150138 | DV37: 15.150138
A38: aoman | BZ38: 80.204479 | DV38: 80.204479
A39: aelec | CA39: 247.64856 | DV39: 247.64856
A40: awatr | CB40: 169.23693 | DV40: 169.23693
A41: acons | CC41: 1630.8609 | DV41: 1630.8609
A42: atrad | CD42: 1701.6616 | DV42: 1701.6616
A43: atran | CE43: 906.18057 | DV43: 906.18057
...

Sheet LES
A1: Households LES parametrization | R1: abecr | S1: cbecr
A2: DO NOT CHANGE ANYTHING UNLESS INSTRUCTED (BLACK cells should NOT be changed; color cells CAN be changed). Follow steps. | R2: aocrp | S2: cocrp
A4: STEP 0: classification
A6: SAM 4 letters | B6: cere | C6: gmll | D6: root | E6: puls | F6: vege | G6: frui | H6: fveg | I6: live | J6: fish | K6: meat | L6: fsea | M6: milk | N6: dair | O6: oils | P6: foil | Q6: fobe | R6: text | S6: elec | T6: watr | U6: real | V6: educ | W6: heal | X6: padm | Y6: becr | Z6: ocrp | AA6: fore | AB6: oapr | AC6: mine | AD6: mino | AE6: wood | AF6: petr | AG6: fert | AH6: chem | AI6: nmet | AJ6: metl | AK6: mach | AL6: oman | AM6: cons | AN6: hotl | AO6: rest | AP6: trad | AQ6: tran | AR6: comm | AS6: fsrv | AT6: bsrv | AU6: osrv
A7: SAM commodities | B7: ="c"&B6 -> ccere | C7: ="c"&C6 -> cgmll | D7: ="c"&D6 -> croot | E7: ="c"&E6 -> cpuls | F7: ="c"&F6 -> cvege | G7: ="c"&G6 -> cfrui | H7: ="c"&H6 -> cfveg | I7: ="c"&I6 -> clive | ... X7: ="c"&X6 -> cpadm | Y7: cbecr | Z7: ="c"&Z6 -> cocrp | AA7: ="c"&AA6 -> cfore | AB7: ="c"&AB6 -> coapr | AC7: ="c"&AC6 -> cmine | AD7: ="c"&AD6 -> cmino | AE7: ="c"&AE6 -> cwood | AF7: ="c"&AF6 -> cpetr | AG7: ="c"&AG6 -> cfert | ... AU7: ="c"&AU6 -> cosrv
A8: SAM activities | B8: ="a"&B6 -> acere | C8: ="a"&C6 -> agmll | D8: ="a"&D6 -> aroot | E8: ="a"&E6 -> apuls | F8: ="a"&F6 -> avege | G8: ="a"&G6 -> afrui | H8: ="a"&H6 -> afveg | I8: ="a"&I6 -> alive | ... X8: ="a"&X6 -> apadm | Y8: abecr | Z8: ="a"&Z6 -> aocrp | AA8: ="a"&AA6 -> afore | AB8: ="a"&AB6 -> aoapr | AC8: ="a"&AC6 -> amine | AD8: ="a"&AD6 -> amino | AE8: ="a"&AE6 -> awood | AF8: ="a"&AF6 -> apetr | AG8: ="a"&AG6 -> afert | ... AU8: ="a"&AU6 -> aosrv
A9: broad categories | B9: cereals | C9: cereals | D9: roots | E9: pulses | F9: vegetables | G9: fruits | H9: fruits | I9: fish-meat-egg | J9: fish-meat-egg | K9: fish-meat-egg | L9: fish-meat-egg | M9: diary | N9: diary | O9: fats & oils | P9: fats & oils | Q9: other food | R9: clothing and textile | S9: utilities | T9: utilities | U9: housing | V9: education, health and public | W9: education, health and public | X9: education, health and public | Y9: other ag | Z9: other ag | AA9: other ag | AB9: other ag | AC9: mining | AD9: mining | AE9: manufacturing | AF9: manufacturing | AG9: manufacturing | AH9: manufacturing | AI9: manufacturing | AJ9: manufacturing | AK9: manufacturing | AL9: manufacturing | AM9: contruction | AN9: hotels and restaurants | AO9: hotels and restaurants | AP9: trade, transport and comm | AQ9: trade, transport and comm | AR9: other services | AS9: other services | AT9: other services | AU9: other services
A10: given - residual categories | B10: =VLOOKUP(B9,$R$102:$S$122,2,FALSE) -> given | C10: =VLOOKUP(C9,$R$102:$S$122,2,FALSE) -> given | D10: =VLOOKUP(D9,$R$102:$S$122,2,FALSE) -> given | E10: =VLOOKUP(E9,$R$102:$S$122,2,FALSE) -> given | F10: =VLOOKUP(F9,$R$102:$S$122,2,FALSE) -> given | G10: =VLOOKUP(G9,$R$102:$S$122,2,FALSE) -> given | H10: =VLOOKUP(H9,$R$102:$S$122,2,FALSE) -> given | I10: =VLOOKUP(I9,$R$102:$S$122,2,FALSE) -> given | ... AU10: =VLOOKUP(AU9,$R$102:$S$122,2,FALSE) -> residual
A12: given=income elasticity WILL bew given
A13: residual = income elasticity WILL be calculated/calibrated as a residual
A15: STEP 1: calculate ABS - average budget shares (based on SAM).
A16: 20 groups - ABS | U16: SAM values
A17: given - residual categories | B17: caregory | C17: Rural farm | H17: Rural nonfarm | M17: Urban | R17: Total national | U17: Rural farm | Z17: Rural nonfarm | AE17: Urban | AJ17: total
C18: hhd-f1 | D18: hhd-f2 | E18: hhd-f3 | F18: hhd-f4 | G18: hhd-f5 | H18: hhd-n1 | I18: hhd-n2 | J18: hhd-n3 | K18: hhd-n4 | L18: hhd-n5 | M18: hhd-u1 | N18: hhd-u2 | O18: hhd-u3 | P18: hhd-u4 | Q18: hhd-u5 | U18: hhd-f1 | V18: hhd-f2 | W18: hhd-f3 | X18: hhd-f4 | Y18: hhd-f5 | Z18: hhd-n1 | AA18: hhd-n2 | AB18: hhd-n3 | AC18: hhd-n4 | AD18: hhd-n5 | AE18: hhd-u1 | AF18: hhd-u2 | AG18: hhd-u3 | AH18: hhd-u4 | AI18: hhd-u5
A19: =S102 -> given | B19: cereals | C19: =SUM(C49:C50) -> 27.395786 | D19: =SUM(D49:D50) -> 23.713124 | E19: =SUM(E49:E50) -> 20.370575 | F19: =SUM(F49:F50) -> 16.654798 | G19: =SUM(G49:G50) -> 11.191999 | H19: =SUM(H49:H50) -> 22.377673 | I19: =SUM(I49:I50) -> 18.222094 | J19: =SUM(J49:J50) -> 19.661903 | ... R19: =SUM(R49:R50) -> 12.541841 | T19: cereals | U19: =SUM(U49:U50) -> 71.893521 | V19: =SUM(V49:V50) -> 88.647541 | W19: =SUM(W49:W50) -> 118.7404 | X19: =SUM(X49:X50) -> 133.01273 | Y19: =SUM(Y49:Y50) -> 160.01767 | Z19: =SUM(Z49:Z50) -> 3.8669753 | AA19: =SUM(AA49:AA50) -> 4.0642792 | AB19: =SUM(AB49:AB50) -> 5.4025494 | ... AJ19: =SUM(AJ49:AJ50) -> 819.20191
A20: =S103 -> given | B20: roots | C20: =SUM(C51:C51) -> 4.4549956 | D20: =SUM(D51:D51) -> 4.5106084 | E20: =SUM(E51:E51) -> 4.7593821 | F20: =SUM(F51:F51) -> 4.9215352 | G20: =SUM(G51:G51) -> 3.7079649 | H20: =SUM(H51:H51) -> 2.3900328 | I20: =SUM(I51:I51) -> 3.2232009 | J20: =SUM(J51:J51) -> 4.0713657 | ... R20: =SUM(R51:R51) -> 3.1875478 | T20: roots | U20: =SUM(U51:U51) -> 11.691043 | V20: =SUM(V51:V51) -> 16.862154 | W20: =SUM(W51:W51) -> 27.742512 | X20: =SUM(X51:X51) -> 39.305601 | Y20: =SUM(Y51:Y51) -> 53.01465 | Z20: =SUM(Z51:Z51) -> 0.41300977 | AA20: =SUM(AA51:AA51) -> 0.71890686 | AB20: =SUM(AB51:AB51) -> 1.1186992 | ... AJ20: =SUM(AJ51:AJ51) -> 208.2027
A21: =S104 -> given | B21: pulses | C21: =C52 -> 2.9322489 | D21: =D52 -> 3.1664244 | E21: =E52 -> 3.1118736 | F21: =F52 -> 2.7947241 | G21: =G52 -> 2.1223303 | H21: =H52 -> 1.6435541 | I21: =I52 -> 2.2440819 | J21: =J52 -> 1.9466825 | ... R21: =R52 -> 1.9069241 | T21: pulses | U21: =U52 -> 7.6949681 | V21: =V52 -> 11.837147 | W21: =W52 -> 18.139159 | X21: =X52 -> 22.319927 | Y21: =Y52 -> 30.344031 | Z21: =Z52 -> 0.28401448 | AA21: =AA52 -> 0.50052289 | AB21: =AB52 -> 0.53489473 | ... AJ21: =AJ52 -> 124.55554
A22: =S105 -> given | B22: vegetables | C22: =SUM(C53:C53) -> 11.354009 | D22: =SUM(D53:D53) -> 9.837339 | E22: =SUM(E53:E53) -> 8.1848849 | F22: =SUM(F53:F53) -> 7.1705287 | G22: =SUM(G53:G53) -> 4.6493467 | H22: =SUM(H53:H53) -> 9.1680143 | I22: =SUM(I53:I53) -> 7.6729356 | J22: =SUM(J53:J53) -> 6.2326773 | ... R22: =SUM(R53:R53) -> 5.2548374 | T22: vegetables | U22: =SUM(U53:U53) -> 29.795811 | V22: =SUM(V53:V53) -> 36.775244 | W22: =SUM(W53:W53) -> 47.70982 | X22: =SUM(X53:X53) -> 57.267077 | Y22: =SUM(Y53:Y53) -> 66.474063 | Z22: =SUM(Z53:Z53) -> 1.5842793 | AA22: =SUM(AA53:AA53) -> 1.7113814 | AB22: =SUM(AB53:AB53) -> 1.7125681 | ... AJ22: =SUM(AJ53:AJ53) -> 343.23293
A23: =S106 -> given | B23: fruits | C23: =SUM(C54:C55) -> 1.9732792 | D23: =SUM(D54:D55) -> 1.8538833 | E23: =SUM(E54:E55) -> 2.1548294 | F23: =SUM(F54:F55) -> 2.1070058 | G23: =SUM(G54:G55) -> 2.2628935 | H23: =SUM(H54:H55) -> 1.4406041 | I23: =SUM(I54:I55) -> 1.7757437 | J23: =SUM(J54:J55) -> 1.6520126 | ... R23: =SUM(R54:R55) -> 1.7505289 | T23: fruits | U23: =SUM(U54:U55) -> 5.1783874 | V23: =SUM(V54:V55) -> 6.9304322 | W23: =SUM(W54:W55) -> 12.560534 | X23: =SUM(X54:X55) -> 16.827499 | Y23: =SUM(Y54:Y55) -> 32.353733 | Z23: =SUM(Z54:Z55) -> 0.24894369 | AA23: =SUM(AA54:AA55) -> 0.39606415 | AB23: =SUM(AB54:AB55) -> 0.45392757 | ... AJ23: =SUM(AJ54:AJ55) -> 114.3402
A24: =S107 -> given | B24: fish-meat-egg | C24: =SUM(C56:C59) -> 8.0372657 | D24: =SUM(D56:D59) -> 11.599026 | E24: =SUM(E56:E59) -> 13.40559 | F24: =SUM(F56:F59) -> 16.058805 | G24: =SUM(G56:G59) -> 18.790411 | H24: =SUM(H56:H59) -> 8.586381 | I24: =SUM(I56:I59) -> 12.241586 | J24: =SUM(J56:J59) -> 14.896385 | ... R24: =SUM(R56:R59) -> 13.392203 | T24: fish-meat-egg | U24: =SUM(U56:U59) -> 21.091833 | V24: =SUM(V56:V59) -> 43.361017 | W24: =SUM(W56:W59) -> 78.141393 | X24: =SUM(X56:X59) -> 128.25286 | Y24: =SUM(Y56:Y59) -> 268.65602 | Z24: =SUM(Z56:Z59) -> 1.4837701 | AA24: =SUM(AA56:AA59) -> 2.730379 | AB24: =SUM(AB56:AB59) -> 4.0931164 | ... AJ24: =SUM(AJ56:AJ59) -> 874.74541
A25: =S108 -> given | B25: diary | C25: =SUM(C60:C61) -> 0.043847645 | D25: =SUM(D60:D61) -> 0.217089 | E25: =SUM(E60:E61) -> 0.28331335 | F25: =SUM(F60:F61) -> 0.62149634 | G25: =SUM(G60:G61) -> 0.93523285 | H25: =SUM(H60:H61) -> 0.16777877 | I25: =SUM(I60:I61) -> 0.081452677 | J25: =SUM(J60:J61) -> 0.35656961 | ... R25: =SUM(R60:R61) -> 0.73724779 | T25: diary | U25: =SUM(U60:U61) -> 0.11506739 | V25: =SUM(V60:V61) -> 0.81155083 | W25: =SUM(W60:W61) -> 1.6514379 | X25: =SUM(X60:X61) -> 4.9635501 | Y25: =SUM(Y60:Y61) -> 13.371497 | Z25: =SUM(Z60:Z61) -> 0.028993022 | AA25: =SUM(AA60:AA61) -> 0.018167309 | AB25: =SUM(AB60:AB61) -> 0.097975508 | ... AJ25: =SUM(AJ60:AJ61) -> 48.155194
A26: =S109 -> given | B26: fats & oils | C26: =SUM(C62:C63) -> 2.0175182 | D26: =SUM(D62:D63) -> 2.6745589 | E26: =SUM(E62:E63) -> 3.1645926 | F26: =SUM(F62:F63) -> 3.9300724 | G26: =SUM(G62:G63) -> 4.1479601 | H26: =SUM(H62:H63) -> 2.3829687 | I26: =SUM(I62:I63) -> 2.88201 | J26: =SUM(J62:J63) -> 3.1303228 | ... R26: =SUM(R62:R63) -> 5.2463671 | T26: fats & oils | U26: =SUM(U62:U63) -> 5.2944818 | V26: =SUM(V62:V63) -> 9.9983902 | W26: =SUM(W62:W63) -> 18.446459 | X26: =SUM(X62:X63) -> 31.387331 | Y26: =SUM(Y62:Y63) -> 59.305485 | Z26: =SUM(Z62:Z63) -> 0.41178907 | AA26: =SUM(AA62:AA63) -> 0.64280719 | AB26: =SUM(AB62:AB63) -> 0.8601265 | ... AJ26: =SUM(AJ62:AJ63) -> 342.67966
A27: =S110 -> given | B27: other food | C27: =SUM(C64:C64) -> 3.836133 | D27: =SUM(D64:D64) -> 5.0076941 | E27: =SUM(E64:E64) -> 5.791494 | F27: =SUM(F64:F64) -> 7.0764406 | G27: =SUM(G64:G64) -> 7.2534209 | H27: =SUM(H64:H64) -> 4.7669589 | I27: =SUM(I64:I64) -> 4.1139952 | J27: =SUM(J64:J64) -> 5.9117649 | ... R27: =SUM(R64:R64) -> 6.622549 | T27: other food | U27: =SUM(U64:U64) -> 10.06699 | V27: =SUM(V64:V64) -> 18.720425 | W27: =SUM(W64:W64) -> 33.758708 | X27: =SUM(X64:X64) -> 56.515647 | Y27: =SUM(Y64:Y64) -> 103.70583 | Z27: =SUM(Z64:Z64) -> 0.82375465 | AA27: =SUM(AA64:AA64) -> 0.91759074 | AB27: =SUM(AB64:AB64) -> 1.6243902 | ... AJ27: =SUM(AJ64:AJ64) -> 432.56845
A28: =S111 -> given | B28: clothing and textile | C28: =SUM(C65:C65) -> 1.8503207 | D28: =SUM(D65:D65) -> 1.9200177 | E28: =SUM(E65:E65) -> 2.1531963 | F28: =SUM(F65:F65) -> 2.2573789 | G28: =SUM(G65:G65) -> 2.305715 | H28: =SUM(H65:H65) -> 1.7677368 | I28: =SUM(I65:I65) -> 1.8204844 | J28: =SUM(J65:J65) -> 1.7634531 | ... R28: =SUM(R65:R65) -> 2.1784506 | T28: clothing and textile | U28: =SUM(U65:U65) -> 4.855713 | V28: =SUM(V65:V65) -> 7.1776645 | W28: =SUM(W65:W65) -> 12.551015 | X28: =SUM(X65:X65) -> 18.028446 | Y28: =SUM(Y65:Y65) -> 32.965974 | Z28: =SUM(Z65:Z65) -> 0.30547387 | AA28: =SUM(AA65:AA65) -> 0.40604317 | AB28: =SUM(AB65:AB65) -> 0.48454834 | ... AJ28: =SUM(AJ65:AJ65) -> 142.29098
A29: =S112 -> given | B29: utilities | C29: =SUM(C66:C67) -> 0.35008961 | D29: =SUM(D66:D67) -> 0.493999 | E29: =SUM(E66:E67) -> 0.50787984 | F29: =SUM(F66:F67) -> 0.63626062 | G29: =SUM(G66:G67) -> 1.4296236 | H29: =SUM(H66:H67) -> 0.62226152 | I29: =SUM(I66:I67) -> 1.1888797 | J29: =SUM(J66:J67) -> 1.1889695 | ... R29: =SUM(R66:R67) -> 2.7744334 | T29: utilities | U29: =SUM(U66:U67) -> 0.91872431 | V29: =SUM(V66:V67) -> 1.8467325 | W29: =SUM(W66:W67) -> 2.9604394 | X29: =SUM(X66:X67) -> 5.0814643 | Y29: =SUM(Y66:Y67) -> 20.440052 | Z29: =SUM(Z66:Z67) -> 0.10752994 | AA29: =SUM(AA66:AA67) -> 0.26516925 | AB29: =SUM(AB66:AB67) -> 0.32669608 | ... AJ29: =SUM(AJ66:AJ67) -> 181.2191
A30: =S113 -> given | B30: housing | C30: =C68 -> 10.393127 | D30: =D68 -> 8.881227 | E30: =E68 -> 7.9823631 | F30: =F68 -> 6.9727339 | G30: =G68 -> 6.3014515 | H30: =H68 -> 11.011433 | I30: =I68 -> 9.4200876 | J30: =J68 -> 9.1892564 | ... R30: =R68 -> 8.8806238 | T30: housing | U30: =U68 -> 27.274212 | V30: =V68 -> 33.200979 | W30: =W68 -> 46.529317 | X30: =X68 -> 55.687398 | Y30: =Y68 -> 90.09504 | Z30: =Z68 -> 1.9028314 | AA30: =AA68 -> 2.1010684 | AB30: =AB68 -> 2.5249546 | ... AJ30: =AJ68 -> 580.06028
A31: =S114 -> given | B31: education, health and public | C31: =SUM(C69:C71) -> 12.103158 | D31: =SUM(D69:D71) -> 12.540297 | E31: =SUM(E69:E71) -> 13.451316 | F31: =SUM(F69:F71) -> 12.783048 | G31: =SUM(G69:G71) -> 13.634957 | H31: =SUM(H69:H71) -> 20.367463 | I31: =SUM(I69:I71) -> 22.4638 | J31: =SUM(J69:J71) -> 14.514947 | ... R31: =SUM(R69:R71) -> 13.360135 | T31: education, health and public | U31: =SUM(U69:U71) -> 31.76177 | V31: =SUM(V69:V71) -> 46.8798 | W31: =SUM(W69:W71) -> 78.407927 | X31: =SUM(X69:X71) -> 102.09119 | Y31: =SUM(Y69:Y71) -> 194.94589 | Z31: =SUM(Z69:Z71) -> 3.5196007 | AA31: =SUM(AA69:AA71) -> 5.0103546 | AB31: =SUM(AB69:AB71) -> 3.9883077 | ... AJ31: =SUM(AJ69:AJ71) -> 872.65085
A32: =S116 -> residual | B32: other ag | C32: =SUM(C72:C75) -> 3.1126926 | D32: =SUM(D72:D75) -> 2.1630819 | E32: =SUM(E72:E75) -> 2.1038137 | F32: =SUM(F72:F75) -> 2.5903922 | G32: =SUM(G72:G75) -> 2.0816301 | H32: =SUM(H72:H75) -> 2.0708763 | I32: =SUM(I72:I75) -> 1.2556523 | J32: =SUM(J72:J75) -> 2.2830951 | ... R32: =SUM(R72:R75) -> 1.8346686 | T32: other ag | U32: =SUM(U72:U75) -> 8.1684983 | V32: =SUM(V72:V75) -> 8.0863191 | W32: =SUM(W72:W75) -> 12.263163 | X32: =SUM(X72:X75) -> 20.68804 | Y32: =SUM(Y72:Y75) -> 29.762119 | Z32: =SUM(Z72:Z75) -> 0.35785793 | AA32: =SUM(AA72:AA75) -> 0.28006229 | AB32: =SUM(AB72:AB75) -> 0.62733166 | ... AJ32: =SUM(AJ72:AJ75) -> 119.836
A33: =S117 -> residual | B33: mining | C33: =SUM(C76:C77) -> 0 | D33: =SUM(D76:D77) -> 0 | E33: =SUM(E76:E77) -> 0 | F33: =SUM(F76:F77) -> 0 | G33: =SUM(G76:G77) -> 0 | H33: =SUM(H76:H77) -> 0 | I33: =SUM(I76:I77) -> 0 | J33: =SUM(J76:J77) -> 0 | ... R33: =SUM(R76:R77) -> 0 | T33: mining | U33: =SUM(U76:U77) -> 0 | V33: =SUM(V76:V77) -> 0 | W33: =SUM(W76:W77) -> 0 | X33: =SUM(X76:X77) -> 0 | Y33: =SUM(Y76:Y77) -> 0 | Z33: =SUM(Z76:Z77) -> 0 | AA33: =SUM(AA76:AA77) -> 0 | AB33: =SUM(AB76:AB77) -> 0 | ... AJ33: =SUM(AJ76:AJ77) -> 0
A34: =S118 -> residual | B34: manufacturing | C34: =SUM(C78:C85) -> 3.884739 | D34: =SUM(D78:D85) -> 3.5597892 | E34: =SUM(E78:E85) -> 3.3927911 | F34: =SUM(F78:F85) -> 3.4842031 | G34: =SUM(G78:G85) -> 4.9017339 | H34: =SUM(H78:H85) -> 3.8084335 | I34: =SUM(I78:I85) -> 3.3631809 | J34: =SUM(J78:J85) -> 3.2867233 | ... R34: =SUM(R78:R85) -> 4.9769638 | T34: manufacturing | U34: =SUM(U78:U85) -> 10.194545 | V34: =SUM(V78:V85) -> 13.307675 | W34: =SUM(W78:W85) -> 19.776631 | X34: =SUM(X78:X85) -> 27.826417 | Y34: =SUM(Y78:Y85) -> 70.08257 | Z34: =SUM(Z78:Z85) -> 0.6581166 | AA34: =SUM(AA78:AA85) -> 0.75012817 | AB34: =SUM(AB78:AB85) -> 0.90310104 | ... AJ34: =SUM(AJ78:AJ85) -> 325.08291
A35: =S119 -> residual | B35: contruction | C35: =C86 -> 0 | D35: =D86 -> 0 | E35: =E86 -> 0 | F35: =F86 -> 0 | G35: =G86 -> 0 | H35: =H86 -> 0 | I35: =I86 -> 0 | J35: =J86 -> 0 | ... R35: =R86 -> 0 | T35: contruction | U35: =U86 -> 0 | V35: =V86 -> 0 | W35: =W86 -> 0 | X35: =X86 -> 0 | Y35: =Y86 -> 0 | Z35: =Z86 -> 0 | AA35: =AA86 -> 0 | AB35: =AB86 -> 0 | ... AJ35: =AJ86 -> 0
A36: =S120 -> residual | B36: hotels and restaurants | C36: =SUM(C87,C88) -> 0.84084045 | D36: =SUM(D87,D88) -> 1.1788274 | E36: =SUM(E87,E88) -> 1.3145768 | F36: =SUM(F87,F88) -> 1.4019035 | G36: =SUM(G87,G88) -> 1.4979372 | H36: =SUM(H87,H88) -> 1.5570112 | I36: =SUM(I87,I88) -> 1.7069852 | J36: =SUM(J87,J88) -> 1.89345 | ... R36: =SUM(R87,R88) -> 1.881235 | T36: hotels and restaurants | U36: =SUM(U87,U88) -> 2.2065795 | V36: =SUM(V87,V88) -> 4.4068486 | W36: =SUM(W87,W88) -> 7.6626882 | X36: =SUM(X87,X88) -> 11.196234 | Y36: =SUM(Y87,Y88) -> 21.416767 | Z36: =SUM(Z87,Z88) -> 0.26905942 | AA36: =SUM(AA87,AA88) -> 0.38072817 | AB36: =SUM(AB87,AB88) -> 0.52026791 | ... AJ36: =SUM(AJ87,AJ88) -> 122.8776
A37: =S121 -> residual | B37: trade, transport and comm | C37: =SUM(C89:C91) -> 2.5409139 | D37: =SUM(D89:D91) -> 3.8408215 | E37: =SUM(E89:E91) -> 5.026292 | F37: =SUM(F89:F91) -> 5.7880299 | G37: =SUM(G89:G91) -> 9.2024702 | H37: =SUM(H89:H91) -> 3.2636186 | I37: =SUM(I89:I91) -> 3.5938841 | J37: =SUM(J89:J91) -> 5.7210977 | ... R37: =SUM(R89:R91) -> 8.9015702 | T37: trade, transport and comm | U37: =SUM(U89:U91) -> 6.6680054 | V37: =SUM(V89:V91) -> 14.358268 | W37: =SUM(W89:W91) -> 29.298334 | X37: =SUM(X89:X91) -> 46.225818 | Y37: =SUM(Y89:Y91) -> 131.57237 | Z37: =SUM(Z89:Z91) -> 0.56396983 | AA37: =SUM(AA89:AA91) -> 0.80158451 | AB37: =SUM(AB89:AB91) -> 1.5720001 | ... AJ37: =SUM(AJ89:AJ91) -> 581.42845
A38: =S122 -> residual | B38: other services | C38: =SUM(C92:C94) -> 2.8790359 | D38: =SUM(D92:D94) -> 2.8421909 | E38: =SUM(E92:E94) -> 2.841236 | F38: =SUM(F92:F94) -> 2.750644 | G38: =SUM(G92:G94) -> 3.5829215 | H38: =SUM(H92:H94) -> 2.6072015 | I38: =SUM(I92:I94) -> 2.7299458 | J38: =SUM(J92:J94) -> 2.2993241 | ... R38: =SUM(R92:R94) -> 4.5718731 | T38: other services | U38: =SUM(U92:U94) -> 7.5553237 | V38: =SUM(V92:V94) -> 10.625055 | W38: =SUM(W92:W94) -> 16.561608 | X38: =SUM(X92:X94) -> 21.967884 | Y38: =SUM(Y92:Y94) -> 51.226842 | Z38: =SUM(Z92:Z94) -> 0.45053764 | AA38: =SUM(AA92:AA94) -> 0.60889061 | AB38: =SUM(AB92:AB94) -> 0.63179095 | ... AJ38: =SUM(AJ92:AJ94) -> 298.62339
A39: Total food | C39: =SUM(C19:C27) -> 62.045083 | D39: =SUM(D19:D27) -> 62.579748 | E39: =SUM(E19:E27) -> 61.226535 | F39: =SUM(F19:F27) -> 61.335406 | G39: =SUM(G19:G27) -> 55.06156 | H39: =SUM(H19:H27) -> 52.923965 | I39: =SUM(I19:I27) -> 52.4571 | J39: =SUM(J19:J27) -> 57.859684 | ... R39: =SUM(R19:R27) -> 50.640046 | T39: Total food | U39: =SUM(U19:U27) -> 162.8221 | V39: =SUM(V19:V27) -> 233.9439 | W39: =SUM(W19:W27) -> 356.89042 | X39: =SUM(X19:X27) -> 489.85222 | Y39: =SUM(Y19:Y27) -> 787.24298 | Z39: =SUM(Z19:Z27) -> 9.1455294 | AA39: =SUM(AA19:AA27) -> 11.700099 | AB39: =SUM(AB19:AB27) -> 15.898247 | ... AJ39: =SUM(AJ19:AJ27) -> 3307.682
A40: Total nonfood | C40: =SUM(C28:C38) -> 37.954917 | D40: =SUM(D28:D38) -> 37.420252 | E40: =SUM(E28:E38) -> 38.773465 | F40: =SUM(F28:F38) -> 38.664594 | G40: =SUM(G28:G38) -> 44.93844 | H40: =SUM(H28:H38) -> 47.076035 | I40: =SUM(I28:I38) -> 47.5429 | J40: =SUM(J28:J38) -> 42.140316 | ... R40: =SUM(R28:R38) -> 49.359954 | T40: Total nonfood | U40: =SUM(U29:U38) -> 94.747659 | V40: =SUM(V29:V38) -> 132.71168 | W40: =SUM(W29:W38) -> 213.46011 | X40: =SUM(X29:X38) -> 290.76444 | Y40: =SUM(Y29:Y38) -> 609.54165 | Z40: =SUM(Z29:Z38) -> 7.8295034 | AA40: =SUM(AA29:AA38) -> 10.197986 | AB40: =SUM(AB29:AB38) -> 11.09445 | ... AJ40: =SUM(AJ29:AJ38) -> 3081.7786
A41: Total given | C41: =SUM(C19:C31) -> 86.741778 | D41: =SUM(D19:D31) -> 86.415289 | E41: =SUM(E19:E31) -> 85.32129 | F41: =SUM(F19:F31) -> 83.984827 | G41: =SUM(G19:G31) -> 78.733307 | H41: =SUM(H19:H31) -> 86.692859 | I41: =SUM(I19:I31) -> 87.350352 | J41: =SUM(J19:J31) -> 84.51631 | ... R41: =SUM(R19:R31) -> 77.833689
A42: Total residual | C42: =SUM(C32:C38) -> 13.258222 | D42: =SUM(D32:D38) -> 13.584711 | E42: =SUM(E32:E38) -> 14.67871 | F42: =SUM(F32:F38) -> 16.015173 | G42: =SUM(G32:G38) -> 21.266693 | H42: =SUM(H32:H38) -> 13.307141 | I42: =SUM(I32:I38) -> 12.649648 | J42: =SUM(J32:J38) -> 15.48369 | ... R42: =SUM(R32:R38) -> 22.166311
A43: Total | C43: =C39+C40 -> 100 | D43: =D39+D40 -> 100 | E43: =E39+E40 -> 100 | F43: =F39+F40 -> 100 | G43: =G39+G40 -> 100 | H43: =H39+H40 -> 100 | I43: =I39+I40 -> 100 | J43: =J39+J40 -> 100 | ... R43: =R39+R40 -> 100 | T43: Total | U43: =U39+U40 -> 257.56976 | V43: =V39+V40 -> 366.65558 | W43: =W39+W40 -> 570.35053 | X43: =X39+X40 -> 780.61666 | Y43: =Y39+Y40 -> 1396.7846 | Z43: =Z39+Z40 -> 16.975033 | AA43: =AA39+AA40 -> 21.898085 | AB43: =AB39+AB40 -> 26.992697 | ... AJ43: =AJ39+AJ40 -> 6389.4606
A46: ABS - disagg
...

Sheet Elasticities
A1: Factor and Trade Substitution Elasticities
A2: Instruction | B2: Enter elasticities if available.
B4: * | F4: *
A5: Trade elasticities (TRADELAS) | E5: Production elasticities (PRODELAS)
B6: Armington | C6: Transformation | F6: Factor substitution | J6: Assigned GTAP elasticities | M6: Original GTAP elasticities
B7: SIGMAQ | C7: SIGMAT | F7: PRODELAS | G7: PRODELAS2 | K7: Mapped | N7: Armington | O7: Region | P7: Factor
A8: ccere | B8: =K8 -> 1.3 | C8: =B8 -> 1.3 | E8: acere | F8: 0.5 | G8: 0.5 | J8: ccere | K8: =N10 -> 1.3 | M8: Paddy rice | N8: 5.05 | O8: 10.1 | P8: 0.24 | R8: =P8 -> 0.24 | S8: =R8 -> 0.24
A9: cpuls | B9: =K9 -> 1.85 | C9: =B9 -> 1.85 | E9: apuls | F9: 0.5 | G9: 0.5 | J9: cpuls | K9: =N11 -> 1.85 | M9: Wheat | N9: 4.45 | O9: 8.9 | P9: 0.24 | R9: =R8 -> 0.24 | S9: =R9 -> 0.24
A10: coils | B10: =K10 -> 2.45 | C10: =B10 -> 2.45 | E10: aoils | F10: 0.5 | G10: 0.5 | J10: coils | K10: =N12 -> 2.45 | M10: Cereal grains nec | N10: 1.3 | O10: 2.6 | P10: 0.24 | R10: =R9 -> 0.24 | S10: =R10 -> 0.24
A11: croot | B11: =K11 -> 1.85 | C11: =B11 -> 1.85 | E11: aroot | F11: 0.5 | G11: 0.5 | J11: croot | K11: =N11 -> 1.85 | M11: Vegetables, fruit, nuts | N11: 1.85 | O11: 3.7 | P11: 0.24 | R11: =R10 -> 0.24 | S11: =R11 -> 0.24
A12: cvege | B12: =K12 -> 1.85 | C12: =B12 -> 1.85 | E12: avege | F12: 0.5 | G12: 0.5 | J12: cvege | K12: =N11 -> 1.85 | M12: Oil seeds | N12: 2.45 | O12: 4.9 | P12: 0.24 | R12: =R11 -> 0.24 | S12: =R12 -> 0.24
A13: cfrui | B13: =K13 -> 1.85 | C13: =B13 -> 1.85 | E13: afrui | F13: 0.5 | G13: 0.5 | J13: cfrui | K13: =N11 -> 1.85 | M13: Sugar cane, sugar beet | N13: 2.7 | O13: 5.4 | P13: 0.24 | R13: =R12 -> 0.24 | S13: =R13 -> 0.24
A14: cbecr | B14: =K14 -> 3.25 | C14: =B14 -> 3.25 | E14: abecr | F14: 0.5 | G14: 0.5 | J14: cbecr | K14: =N15 -> 3.25 | M14: Plant-based fibers | N14: 2.5 | O14: 5 | P14: 0.24 | R14: =R13 -> 0.24 | S14: =R14 -> 0.24
A15: cocrp | B15: =K15 -> 3.25 | C15: =B15 -> 3.25 | E15: aocrp | F15: 0.5 | G15: 0.5 | J15: cocrp | K15: =N15 -> 3.25 | M15: Crops nec | N15: 3.25 | O15: 6.5 | P15: 0.24 | R15: =R14 -> 0.24 | S15: =R15 -> 0.24
A16: clive | B16: =K16 -> 2 | C16: =B16 -> 2 | E16: alive | F16: 0.5 | G16: 0.5 | J16: clive | K16: =N16 -> 2 | M16: Bovine cattle, sheep and goats, | N16: 2 | O16: 4 | P16: 0.24 | R16: =R15 -> 0.24 | S16: =R16 -> 0.24
A17: cmilk | B17: =K17 -> 3.65 | C17: =B17 -> 3.65 | E17: amilk | F17: 0.5 | G17: 0.5 | J17: cmilk | K17: =N18 -> 3.65 | M17: Animal products nec | N17: 1.3 | O17: 2.6 | P17: 0.24 | R17: =P20 -> 0.2 | S17: =R17 -> 0.2
A18: cfore | B18: =K18 -> 2.5 | C18: =B18 -> 2.5 | E18: afore | F18: 0.5 | G18: 0.5 | J18: cfore | K18: =N20 -> 2.5 | M18: Raw milk | N18: 3.65 | O18: 7.3 | P18: 0.24 | R18: =P21 -> 0.2 | S18: =R18 -> 0.2
A19: cfish | B19: =K19 -> 1.25 | C19: =B19 -> 1.25 | E19: afish | F19: 0.5 | G19: 0.5 | J19: cfish | K19: =N21 -> 1.25 | M19: Wool, silk-worm cocoons | N19: 6.45 | O19: 12.9 | P19: 0.24 | R19: =P23 -> 0.2 | S19: =R19 -> 0.2
A20: cmine | B20: =K20 -> 5.2 | C20: =B20 -> 5.2 | E20: amine | F20: 0.5 | G20: 0.5 | J20: cmine | K20: =N23 -> 5.2 | M20: Forestry | N20: 2.5 | O20: 5 | P20: 0.2 | R20: =R19 -> 0.2 | S20: =R20 -> 0.2
A21: cmino | B21: =K21 -> 0.9 | C21: =B21 -> 0.9 | E21: amino | F21: 0.5 | G21: 0.5 | J21: cmino | K21: =N25 -> 0.9 | M21: Fishing | N21: 1.25 | O21: 2.5 | P21: 0.2
A22: cgmll | B22: =K22 -> 2.6 | C22: =B22 -> 2.6 | E22: agmll | F22: =P26 -> 1.12 | G22: =F22 -> 1.12 | J22: cgmll | K22: =N30 -> 2.6 | M22: Coal | N22: 3.05 | O22: 6.1 | P22: 0.2
A23: cfoil | B23: =K23 -> 3.3 | C23: =B23 -> 3.3 | E23: afoil | F23: =F22 -> 1.12 | G23: =F23 -> 1.12 | J23: cfoil | K23: =N28 -> 3.3 | M23: Oil | N23: 5.2 | O23: 10.4 | P23: 0.2
A24: cfveg | B24: =K24 -> 3.65 | C24: =B24 -> 3.65 | E24: afveg | F24: =F23 -> 1.12 | G24: =F24 -> 1.12 | J24: cfveg | K24: =N29 -> 3.65 | M24: Gas | N24: 17.2 | O24: 34.4 | P24: 0.2
A25: cmeat | B25: =K25 -> 3.85 | C25: =B25 -> 3.85 | E25: ameat | F25: =F24 -> 1.12 | G25: =F25 -> 1.12 | J25: cmeat | K25: =N26 -> 3.85 | M25: Minerals nec | N25: 0.9 | O25: 1.8 | P25: 0.2
A26: cfsea | B26: =K26 -> 4.4 | C26: =B26 -> 4.4 | E26: afsea | F26: =F25 -> 1.12 | G26: =F26 -> 1.12 | J26: cfsea | K26: =N27 -> 4.4 | M26: Bovine meat prods | N26: 3.85 | O26: 7.7 | P26: 1.12
A27: cdair | B27: =K27 -> 3.3 | C27: =B27 -> 3.3 | E27: adair | F27: =F26 -> 1.12 | G27: =F27 -> 1.12 | J27: cdair | K27: =N28 -> 3.3 | M27: Meat products nec | N27: 4.4 | O27: 8.8 | P27: 1.12
A28: cfobe | B28: =K28 -> 2 | C28: =B28 -> 2 | E28: afobe | F28: =F27 -> 1.12 | G28: =F28 -> 1.12 | J28: cfobe | K28: =N32 -> 2 | M28: Vegetable oils and fats | N28: 3.3 | O28: 6.6 | P28: 1.12
A29: coapr | B29: =K29 -> 3.75 | C29: =B29 -> 3.75 | E29: aoapr | F29: =F28 -> 1.12 | G29: =F29 -> 1.12 | J29: coapr | K29: =N34 -> 3.75 | M29: Dairy products | N29: 3.65 | O29: 7.3 | P29: 1.12
A30: ctext | B30: 0.5 | C30: =K30 -> 3.75 | E30: atext | F30: =P34 -> 1.26 | G30: =F30 -> 1.26 | J30: ctext | K30: =N34 -> 3.75 | M30: Processed rice | N30: 2.6 | O30: 5.2 | P30: 1.12
A31: cwood | B31: 0.5 | C31: =K31 -> 3.4 | E31: awood | F31: =P37 -> 1.26 | G31: =F31 -> 1.26 | J31: cwood | K31: =N37 -> 3.4 | M31: Sugar | N31: 2.7 | O31: 5.4 | P31: 1.12
A32: cpetr | B32: 0.5 | C32: =K32 -> 2.1 | E32: apetr | F32: =P39 -> 1.26 | G32: =F32 -> 1.26 | J32: cpetr | K32: =N39 -> 2.1 | M32: Food products nec | N32: 2 | O32: 4 | P32: 1.12
A33: cfert | B33: 0.5 | C33: =K33 -> 3.3 | E33: afert | F33: =P40 -> 1.26 | G33: =F33 -> 1.26 | J33: cfert | K33: =N40 -> 3.3 | M33: Beverages and tobacco products | N33: 1.15 | O33: 2.3 | P33: 1.12
A34: cchem | B34: 0.5 | C34: =K34 -> 3.3 | E34: achem | F34: =F33 -> 1.26 | G34: =F34 -> 1.26 | J34: cchem | K34: =N40 -> 3.3 | M34: Textiles | N34: 3.75 | O34: 7.5 | P34: 1.26
A35: cnmet | B35: 0.5 | C35: =K35 -> 2.9 | E35: anmet | F35: =F34 -> 1.26 | G35: =F35 -> 1.26 | J35: cnmet | K35: =N41 -> 2.9 | M35: Wearing apparel | N35: 3.7 | O35: 7.4 | P35: 1.26
A36: cmetl | B36: 0.5 | C36: =K36 -> 2.95 | E36: ametl | F36: =F35 -> 1.26 | G36: =F36 -> 1.26 | J36: cmetl | K36: =N42 -> 2.95 | M36: Leather products | N36: 4.05 | O36: 8.1 | P36: 1.26
A37: cmach | B37: 0.5 | C37: =K37 -> 4.4 | E37: amach | F37: =F36 -> 1.26 | G37: =F37 -> 1.26 | J37: cmach | K37: =N47 -> 4.4 | M37: Wood products | N37: 3.4 | O37: 6.8 | P37: 1.26
A38: coman | B38: 0.5 | C38: =K38 -> 3.75 | E38: aoman | F38: =F37 -> 1.26 | G38: =F38 -> 1.26 | J38: coman | K38: =N49 -> 3.75 | M38: Paper products, publishing | N38: 2.95 | O38: 5.9 | P38: 1.26
A39: celec | B39: =K39 -> 2.8 | C39: =B39 -> 2.8 | E39: aelec | F39: =F38 -> 1.26 | G39: =F39 -> 1.26 | J39: celec | K39: =N50 -> 2.8 | M39: Petroleum, coal products | N39: 2.1 | O39: 4.2 | P39: 1.26
A40: cwatr | B40: =K40 -> 2.8 | C40: =B40 -> 2.8 | E40: awatr | F40: =F39 -> 1.26 | G40: =F40 -> 1.26 | J40: cwatr | K40: =N52 -> 2.8 | M40: Chemical, rubber, plastic products | N40: 3.3 | O40: 6.6 | P40: 1.26
A41: ccons | B41: =K41 -> 0.5 | C41: =B41 -> 0.5 | E41: acons | F41: =P54 -> 1.68 | G41: =F41 -> 1.68 | J41: ccons | K41: 0.5 | M41: Mineral products nec | N41: 2.9 | O41: 5.8 | P41: 1.26
...

Sheet Production
A1: Agricultural Production Quantities | I1: Agricultural Production Quantities
A2: Instruction | B2: Enter land area and quantity produced for crops and livestock (by region if necessary) | I2: Instruction | J2: Enter land area and quantity produced for crops and livestock (by region if necessary)
B4: * | C4: * | J4: * | K4: *
B5: Production | C5: Area | D5: Yield | J5: Production | K5: Area | L5: Yield
B6: 1000mt | C6: 1000ha | D6: mt/ha | J6: 1000mt | K6: 1000ha | L6: mt/ha
B7: x | C7: x | D7: x | J7: x | K7: x | L7: x
B8: prod | C8: area | D8: yield | J8: prod | K8: area | L8: yield
A9: acere | B9: =SUM(J9:J13) -> 3703.148 | C9: =SUM(K9:K13) -> 1976.054 | D9: =IF(C9>0,B9/C9,0) -> 1.8740115 | I9: amaiz | J9: 3391.924 | K9: 1732.516 | L9: 1.9578024
A10: apuls | B10: =J14 -> 690.777 | C10: =K14 -> 735.416 | D10: =IF(C10>0,B10/C10,0) -> 0.93930102 | I10: asorg | J10: 177.93 | K10: 172.249 | L10: 1.0329813
A11: aoils | B11: =SUM(J15:J16) -> 576.458 | C11: =SUM(K15:K16) -> 611.68 | D11: =IF(C11>0,B11/C11,0) -> 0.9424176 | I11: arice | J11: 132.728 | K11: 70.573 | L11: 1.8807193
A12: aroot | B12: =SUM(J17:J20) -> 13190.652 | C12: =SUM(K17:K20) -> 602.947 | D12: =IF(C12>0,B12/C12,0) -> 21.876968 | I12: awhea | J12: 0.566 | K12: 0.716 | L12: 0.79050279
A13: avege | B13: =SUM(J21:J22) -> 1664.915 | C13: =SUM(K21:K22) -> 140.922 | D13: =IF(C13>0,B13/C13,0) -> 11.814443 | I13: aocer | J13: 0 | K13: 0 | L13: 0
A14: afrui | B14: =SUM(J26:J29) -> 3250.774 | C14: =SUM(K26:K29) -> 268.87322 | D14: =IF(C14>0,B14/C14,0) -> 12.09036 | I14: apuls | J14: 690.777 | K14: 735.416 | L14: 0.93930102
A15: abecr | B15: =SUM(J23,J30:J32) -> 2940.121 | C15: =SUM(K23,K30:K32) -> 50.005 | D15: =IF(C15>0,B15/C15,0) -> 58.79654 | I15: agnut | J15: 350 | K15: 400 | L15: 0.875
A16: aocrp | B16: =SUM(J24:J25,J33:J35) -> 122.213 | C16: =SUM(K24:K25,K33:K35) -> 178.652 | D16: =IF(C16>0,B16/C16,0) -> 0.68408414 | I16: aoils | J16: 226.458 | K16: 211.68 | L16: 1.0698129
A17: alive | B17: =SUM(J36,J38:J41) -> 504.219 | C17: =SUM(K36,K38:K41) -> 4198.8237 | D17: =IF(C17>0,B17/C17,0) -> 0.12008578 | I17: acass | J17: 5708.032 | K17: 242.454 | L17: 23.542742
A18: amilk | B18: =J37 -> 202.965 | C18: =K37 -> 287.42304 | D18: =IF(C18>0,B18/C18,0) -> 0.70615424 | I18: aipot | J18: 1113.077 | K18: 70.31 | L18: 15.830991
I19: aspot | J19: 6369.543 | K19: 290.183 | L19: 21.95009
I20: aroot | J20: 0 | K20: 0 | L20: 0
I21: aleaf | J21: 1217.686 | K21: 56.54 | L21: 21.536717
I22: avege | J22: 447.229 | K22: 84.382 | L22: 5.3000521
I23: asugr | J23: 2881 | K23: 26.775 | L23: 107.60037
I24: atoba | J24: 100.327 | K24: 94.915 | L24: 1.0570194
I25: acott | J25: 19.667 | K25: 80.593 | L25: 0.24402864
I26: anuts | J26: 4.94 | K26: 4.805 | L26: 1.0280957
I27: abana | J27: 404.917 | K27: 39.158218 | L27: 10.340537
I28: aplan | J28: 385.185 | K28: 37.25 | L28: 10.340537
I29: afrui | J29: 2455.732 | K29: 187.66 | L29: 13.086071
I30: ateal | J30: 48.121 | K30: 18.145 | L30: 2.6520254
... I41: aoliv | J41: 270 | K41: 2716.442 | L41: 0.099394723

Sheet Employment
A1: Labor Employment
A2: Instruction | B2: Enter either aggregate sector wages or employment numbers
C4: * | H4: * | I4: * | J4: * | K4: * | O4: * | P4: * | Q4: * | R4: * | S4: * | T4: * | U4: * | V4: *
A5: Aggregate sectors | C5: Mapping to subsectors | G5: Sectoral wages (WFBASE) | N5: Sectoral wages (WFBASE)
A6: AL | C6: AL | D6: A | H6: flab-n | I6: flab-p | J6: flab-s | K6: flab-t | O6: flab-rn | P6: flab-rp | Q6: flab-rs | R6: flab-rt | S6: flab-un | T6: flab-up | U6: flab-us | V6: flab-ut
A7: crp | C7: crp_cer | D7: acere | G7: crp | H7: =O7 -> 527.80163 | I7: =P7 -> 922.36663 | J7: =Q7 -> 1557.9343 | K7: =R7 -> 2874.2262 | N7: crp | O7: 527.80163 | P7: 922.36663 | Q7: 1557.9343 | R7: 2874.2262 | S7: 527.80163 | T7: 922.36663 | U7: 1557.9343 | V7: 2874.2262
A8: crp_cer | C8: crp_pul | D8: apuls | G8: crp_cer | H8: =O8 -> 527.80163 | I8: =P8 -> 922.36663 | J8: =Q8 -> 1557.9343 | K8: =R8 -> 2874.2262 | N8: crp_cer | O8: 527.80163 | P8: 922.36663 | Q8: 1557.9343 | R8: 2874.2262 | S8: 527.80163 | T8: 922.36663 | U8: 1557.9343 | V8: 2874.2262
A9: crp_pul | C9: crp_oil | D9: aoils | G9: crp_pul | H9: =O9 -> 527.80163 | I9: =P9 -> 922.36663 | J9: =Q9 -> 1557.9343 | K9: =R9 -> 2874.2262 | N9: crp_pul | O9: 527.80163 | P9: 922.36663 | Q9: 1557.9343 | R9: 2874.2262 | S9: 527.80163 | T9: 922.36663 | U9: 1557.9343 | V9: 2874.2262
A10: crp_oil | C10: crp_rts | D10: aroot | G10: crp_oil | H10: =O10 -> 527.80163 | I10: =P10 -> 922.36663 | J10: =Q10 -> 1557.9343 | K10: =R10 -> 2874.2262 | N10: crp_oil | O10: 527.80163 | P10: 922.36663 | Q10: 1557.9343 | R10: 2874.2262 | S10: 527.80163 | T10: 922.36663 | U10: 1557.9343 | V10: 2874.2262
A11: crp_rts | C11: crp_veg | D11: avege | G11: crp_rts | H11: =O11 -> 527.80163 | I11: =P11 -> 922.36663 | J11: =Q11 -> 1557.9343 | K11: =R11 -> 2874.2262 | N11: crp_rts | O11: 527.80163 | P11: 922.36663 | Q11: 1557.9343 | R11: 2874.2262 | S11: 527.80163 | T11: 922.36663 | U11: 1557.9343 | V11: 2874.2262
A12: crp_veg | C12: crp_fru | D12: afrui | G12: crp_veg | H12: =O12 -> 527.80163 | I12: =P12 -> 922.36663 | J12: =Q12 -> 1557.9343 | K12: =R12 -> 2874.2262 | N12: crp_veg | O12: 527.80163 | P12: 922.36663 | Q12: 1557.9343 | R12: 2874.2262 | S12: 527.80163 | T12: 922.36663 | U12: 1557.9343 | V12: 2874.2262
A13: crp_fru | C13: crp_exp | D13: abecr | G13: crp_fru | H13: =O13 -> 527.80163 | I13: =P13 -> 922.36663 | J13: =Q13 -> 1557.9343 | K13: =R13 -> 2874.2262 | N13: crp_fru | O13: 527.80163 | P13: 922.36663 | Q13: 1557.9343 | R13: 2874.2262 | S13: 527.80163 | T13: 922.36663 | U13: 1557.9343 | V13: 2874.2262
A14: crp_exp | C14: crp_exp | D14: aocrp | G14: crp_exp | H14: =O14 -> 527.80163 | I14: =P14 -> 922.36663 | J14: =Q14 -> 1557.9343 | K14: =R14 -> 2874.2262 | N14: crp_exp | O14: 527.80163 | P14: 922.36663 | Q14: 1557.9343 | R14: 2874.2262 | S14: 527.80163 | T14: 922.36663 | U14: 1557.9343 | V14: 2874.2262
A15: crp_oth | C15: liv | D15: alive | G15: crp_oth | H15: =O15 -> 527.80163 | I15: =P15 -> 922.36663 | J15: =Q15 -> 1557.9343 | K15: =R15 -> 2874.2262 | N15: crp_oth | O15: 527.80163 | P15: 922.36663 | Q15: 1557.9343 | R15: 2874.2262 | S15: 527.80163 | T15: 922.36663 | U15: 1557.9343 | V15: 2874.2262
A16: liv | C16: liv | D16: amilk | G16: liv | H16: =O16 -> 527.80163 | I16: =P16 -> 922.36663 | J16: =Q16 -> 1557.9343 | K16: =R16 -> 2874.2262 | N16: liv | O16: 527.80163 | P16: 922.36663 | Q16: 1557.9343 | R16: 2874.2262 | S16: 527.80163 | T16: 922.36663 | U16: 1557.9343 | V16: 2874.2262
A17: oag | C17: oag_for | D17: afore | G17: oag | H17: =O17 -> 527.80163 | I17: =P17 -> 922.36663 | J17: =Q17 -> 1557.9343 | K17: =R17 -> 2874.2262 | N17: oag | O17: 527.80163 | P17: 922.36663 | Q17: 1557.9343 | R17: 2874.2262 | S17: 527.80163 | T17: 922.36663 | U17: 1557.9343 | V17: 2874.2262
A18: oag_for | C18: oag_fsh | D18: afish | G18: oag_for | H18: =O18 -> 527.80163 | I18: =P18 -> 922.36663 | J18: =Q18 -> 1557.9343 | K18: =R18 -> 2874.2262 | N18: oag_for | O18: 527.80163 | P18: 922.36663 | Q18: 1557.9343 | R18: 2874.2262 | S18: 527.80163 | T18: 922.36663 | U18: 1557.9343 | V18: 2874.2262
... A41: osv | C41: trd | D41: atrad | G41: osv | H41: =O41 -> 1451.9978 | I41: =P41 -> 2247.5547 | J41: =Q41 -> 4657.9661 | K41: =R41 -> 22611.17 | N41: osv | O41: 1451.9978 | P41: 2247.5547 | Q41: 4657.9661 | R41: 22611.17 | S41: 1451.9978 | T41: 2247.5547 | U41: 4657.9661 | V41: 22611.17
C42: trn | D42: atran
C43: hfs | D43: ahotl
C44: hfs | D44: arest
C45: com | D45: acomm
C46: fsv | D46: afsrv
C47: rbs | D47: areal
C48: rbs | D48: absrv | H48: * | I48: * | J48: * | K48: * | O48: * | P48: * | Q48: * | R48: * | S48: * | T48: * | U48: * | V48: *
C49: pad | D49: apadm | G49: Sectoral employment (QFBASE) | N49: Sectoral employment (QFBASE)
C50: edu | D50: aeduc | H50: flab-n | I50: flab-p | J50: flab-s | K50: flab-t | O50: flab-rn | P50: flab-rp | Q50: flab-rs | R50: flab-rt | S50: flab-un | T50: flab-up | U50: flab-us | V50: flab-ut
C51: hsw | D51: aheal | G51: crp | H51: =O51 -> 0 | I51: =P51 -> 0 | J51: =Q51 -> 0 | K51: =R51 -> 0 | N51: crp
C52: osv | D52: aosrv | G52: crp_cer | H52: =O52 -> 0 | I52: =P52 -> 0 | J52: =Q52 -> 0 | K52: =R52 -> 0 | N52: crp_cer
G53: crp_pul | H53: =O53 -> 0 | I53: =P53 -> 0 | J53: =Q53 -> 0 | K53: =R53 -> 0 | N53: crp_pul
G54: crp_oil | H54: =O54 -> 0 | I54: =P54 -> 0 | J54: =Q54 -> 0 | K54: =R54 -> 0 | N54: crp_oil
G55: crp_rts | H55: =O55 -> 0 | I55: =P55 -> 0 | J55: =Q55 -> 0 | K55: =R55 -> 0 | N55: crp_rts
G56: crp_veg | H56: =O56 -> 0 | I56: =P56 -> 0 | J56: =Q56 -> 0 | K56: =R56 -> 0 | N56: crp_veg
G57: crp_fru | H57: =O57 -> 0 | I57: =P57 -> 0 | J57: =Q57 -> 0 | K57: =R57 -> 0 | N57: crp_fru
G58: crp_exp | H58: =O58 -> 0 | I58: =P58 -> 0 | J58: =Q58 -> 0 | K58: =R58 -> 0 | N58: crp_exp
G59: crp_oth | H59: =O59 -> 0 | I59: =P59 -> 0 | J59: =Q59 -> 0 | K59: =R59 -> 0 | N59: crp_oth
G60: liv | H60: =O60 -> 0 | I60: =P60 -> 0 | J60: =Q60 -> 0 | K60: =R60 -> 0 | N60: liv
